Workbook
Name ETE: #REF!
Name GN: #REF!
Name GR: #REF!
Name MANC: #REF!
Name MUN: #REF!
Name NG: #REF!

Sheet IT PEI
A1: Año | B1: N G 1 | C1: N G 2 | D1: Fecha de recepción | E1: Periodo PEI | F1: Vigencia | G1: Tipo de PEI | H1: Estado_PEI | I1: Responsable Institucional | J1: Cantidad de revisiones | K1: Fecha de derivación | L1: Etapas de revisión | M1: Comentario adicional/ Emisor de I.T | N1: Articulación | O1: Expediente | P1: Fecha de I.T | Q1: Número de I.T | R1: Fecha Oficio | S1: Número Oficio | T1: Id_Sector | U1: nombre_sector | V1: Id_Pliego | W1: Nombre_pliego | X1: Id_UE | Y1: Nombre_unidad_ejecutora | Z1: Id_Departamento | AA1: nombre_departamento | AB1: Id_Provincia | AC1: nombre_provincia | AD1: Id_4Distrito | AE1: nombre_distrito | AF1: id_registro | AG1: last_updated | AH1: updated_by
A2: 2016 | B2: GN | C2: GN | D2: 42713 | E2: 2017-2019 | F2: NO | G2: FORMULADO | H2: EMITIDO | P2: 42713 | Q2: 024-2016-CEPLAN/DNCP-FI | T2: 1 | U2: PRESIDENCIA CONSEJO MINISTROS | V2: 23 | W2: AUTORIDAD NACIONAL DEL SERVICIO CIVIL | X2: 1314 | Y2: AUTORIDAD NACIONAL DE SERVICIO CIVIL | Z2: 15 | AA2: LIMA | AB2: 1 | AC2: LIMA | AD2: 13 | AE2: JESUS MARIA
A3: 2016 | B3: GN | C3: GN | D3: 42730 | E3: 2017-2019 | F3: NO | G3: FORMULADO | H3: EMITIDO | P3: 42730 | Q3: 042-2016-CEPLAN/DNCP-FI | T3: 9 | U3: ECONOMIA Y FINANZAS | V3: 96 | W3: CENTRAL DE COMPRAS PÚBLICAS - PERÚ COMPRAS | X3: 1650 | Y3: CENTRAL DE COMPRAS PUBLICAS - PERU COMPRAS | Z3: 15 | AA3: LIMA | AB3: 1 | AC3: LIMA | AD3: 31 | AE3: SAN ISIDRO
A4: 2016 | B4: GN | C4: GN | D4: 42731 | E4: 2017-2019 | F4: NO | G4: FORMULADO | H4: EMITIDO | P4: 42731 | Q4: 046-2016-CEPLAN/DNCP-FI | T4: 26 | U4: DEFENSA | V4: 25 | W4: CENTRO NACIONAL DE ESTIMACION, PREVENCION Y REDUCCION DEL RIESGO DE DESASTRES - CENEPRED | X4: 1410 | Y4: CENTRO NAC. DE ESTIMACION, PREVENCION Y REDUCCION DE RIESGOS DE DESASTRES- CENEPRED | Z4: 15 | AA4: LIMA | AB4: 1 | AC4: LIMA | AD4: 31 | AE4: SAN ISIDRO
A5: 2016 | B5: GN | C5: GN | D5: 42733 | E5: 2017-2019 | F5: NO | G5: FORMULADO | H5: EMITIDO | P5: 42733 | Q5: 055-2016-CEPLAN/DNCP-FI | T5: 1 | U5: PRESIDENCIA CONSEJO MINISTROS | V5: 12 | W5: COMISION NACIONAL PARA EL DESARROLLO Y VIDA SIN DROGAS - DEVIDA | X5: 1064 | Y5: COMISION NAC. PARA EL DESARROLLO Y VIDA SIN DROGAS - DEVIDA | Z5: 15 | AA5: LIMA | AB5: 1 | AC5: LIMA | AD5: 1 | AE5: LIMA
A6: 2016 | B6: GN | C6: GN | D6: 42591 | E6: 2016-2018 | F6: NO | G6: FORMULADO | H6: EMITIDO | P6: 42591 | Q6: 018-2016-CEPLAN/DNCP-FI | T6: 38 | U6: PRODUCCION | V6: 59 | W6: FONDO NACIONAL DE DESARROLLO PESQUERO - FONDEPES | X6: 192 | Y6: FONDO NACIONAL DE DESARROLLO PESQUERO-FONDEPES | Z6: 15 | AA6: LIMA | AB6: 1 | AC6: LIMA | AD6: 1 | AE6: LIMA
A7: 2016 | B7: GR | C7: GR | D7: 42725 | E7: 2017-2019 | F7: NO | G7: FORMULADO | H7: EMITIDO | P7: 42725 | Q7: 038-2016-CEPLAN/DNCP-FI | T7: 99 | U7: GOBIERNOS REGIONALES | V7: 440 | W7: GOBIERNO REGIONAL DEL DEPARTAMENTO DE AMAZONAS | X7: 721 | Y7: REGION AMAZONAS-SEDE CENTRAL | Z7: 1 | AA7: AMAZONAS | AB7: 1 | AC7: CHACHAPOYAS | AD7: 1 | AE7: CHACHAPOYAS
A8: 2016 | B8: GR | C8: GR | D8: 42731 | E8: 2017-2019 | F8: NO | G8: FORMULADO | H8: EMITIDO | P8: 42731 | Q8: 048-2016-CEPLAN/DNCP-FI | T8: 99 | U8: GOBIERNOS REGIONALES | V8: 441 | W8: GOBIERNO REGIONAL DEL DEPARTAMENTO DE ANCASH | X8: 726 | Y8: REGION ANCASH SEDE CENTRAL | Z8: 2 | AA8: ANCASH | AB8: 1 | AC8: HUARAZ | AD8: 1 | AE8: HUARAZ
A9: 2016 | B9: GR | C9: GR | D9: 42444 | E9: 2016-2018 | F9: NO | G9: FORMULADO | H9: EMITIDO | P9: 42444 | Q9: 007-2016-CEPLAN/DNCP-FI | T9: 99 | U9: GOBIERNOS REGIONALES | V9: 444 | W9: GOBIERNO REGIONAL DEL DEPARTAMENTO DE AYACUCHO | X9: 770 | Y9: REGION AYACUCHO-SEDE CENTRAL | Z9: 5 | AA9: AYACUCHO | AB9: 1 | AC9: HUAMANGA | AD9: 1 | AE9: AYACUCHO
A10: 2016 | B10: GR | C10: GR | D10: 42383 | E10: 2015-2017 | F10: NO | G10: FORMULADO | H10: EMITIDO | P10: 42383 | Q10: 002-2016-CEPLAN/DNCP-DHC | T10: 99 | U10: GOBIERNOS REGIONALES | V10: 450 | W10: GOBIERNO REGIONAL DEL DEPARTAMENTO DE JUNIN | X10: 818 | Y10: REGION JUNIN-SEDE CENTRAL | Z10: 12 | AA10: JUNIN | AB10: 1 | AC10: HUANCAYO | AD10: 1 | AE10: HUANCAYO
A11: 2016 | B11: GR | C11: GR | D11: 42384 | E11: 2016-2018 | F11: NO | G11: FORMULADO | H11: EMITIDO | P11: 42384 | Q11: 003-2016-CEPLAN/DNCP-DHC | T11: 99 | U11: GOBIERNOS REGIONALES | V11: 453 | W11: GOBIERNO REGIONAL DEL DEPARTAMENTO DE LORETO | X11: 861 | Y11: REGION LORETO-SEDE CENTRAL | Z11: 16 | AA11: LORETO | AB11: 1 | AC11: MAYNAS | AD11: 12 | AE11: BELEN
A12: 2016 | B12: GR | C12: GR | D12: 42604 | E12: 2015-2017 | F12: NO | G12: FORMULADO | H12: EMITIDO | P12: 42604 | Q12: 019-2016-CEPLAN/DNCP-FI | T12: 99 | U12: GOBIERNOS REGIONALES | V12: 455 | W12: GOBIERNO REGIONAL DEL DEPARTAMENTO DE MOQUEGUA | X12: 880 | Y12: REGION MOQUEGUA-SEDE CENTRAL | Z12: 18 | AA12: MOQUEGUA | AB12: 1 | AC12: MARISCAL NIETO | AD12: 1 | AE12: MOQUEGUA
A13: 2016 | B13: GR | C13: GR | D13: 42734 | E13: 2017-2019 | F13: NO | G13: FORMULADO | H13: EMITIDO | P13: 42734 | Q13: 057-2016-CEPLAN/DNCP-FI | T13: 99 | U13: GOBIERNOS REGIONALES | V13: 456 | W13: GOBIERNO REGIONAL DEL DEPARTAMENTO DE PASCO | X13: 885 | Y13: REGION PASCO-SEDE CENTRAL | Z13: 19 | AA13: PASCO | AB13: 1 | AC13: PASCO | AD13: 13 | AE13: YANACANCHA
... A181: 2018 | B181: GN | C181: GN | D181: 43181 | E181: 2018-2021 | F181: NO | G181: FORMULADO | H181: EMITIDO | P181: 43181 | Q181: 016-2018-CEPLAN/DNCP-PEI | T181: 5 | U181: AMBIENTAL | V181: 5 | W181: M. DEL AMBIENTE | X181: 1293 | Y181: MINISTERIO DEL AMBIENTE - ADMINISTRACION GENERAL | Z181: 15 | AA181: LIMA | AB181: 1 | AC181: LIMA | AD181: 31 | AE181: SAN ISIDRO
A182: 2018 | B182: MANC | C182: MANC | D182: 43159 | E182: 2019-2022 | F182: NO | G182: FORMULADO | H182: EMITIDO | P182: 43159 | Q182: 144-2018-CEPLAN/DNCP-PEI | T182: #N/A | U182: #N/A | V182: #N/A | W182: MANCOMUNIDAD NORVRAEM | X182: #N/D | Y182: MANCOMUNIDAD NORVRAEM | Z182: #N/D | AA182: #N/D | AB182: ## | AC182: #N/D | AD182: #N/D | AE182: #N/D
A183: 2018 | B183: MANC | C183: MANC | D183: 43157 | E183: 2018-2021 | F183: NO | G183: FORMULADO | H183: EMITIDO | P183: 43157 | Q183: 010-2018-CEPLAN/DNCP-PEI | T183: 98 | U183: Mancomunidades Regionales | V183: 360001 | W183: MANCOMUNIDAD REGIONAL DE LOS ANDES | X183: 360001 | Y183: MANCOMUNIDAD REGIONAL DE LOS ANDES | Z183: #N/D | AA183: #N/D | AB183: ## | AC183: #N/D | AD183: #N/D | AE183: #N/D
A184: 2018 | B184: GN | C184: GN | D184: 43465 | E184: 2019-2022 | F184: NO | G184: FORMULADO | H184: EMITIDO | P184: 43465 | Q184: 138-2018-CEPLAN/DNCP-PEI | T184: 39 | U184: MUJER Y POBLACIONES VULNERABLES | V184: 39 | W184: MINISTERIO DE LA MUJER Y POBLACIONES VULNERABLES | X184: 1087 | Y184: MINISTERIO DE LA MUJER Y POBLACIONES VULNERABLES- ADM. NIVEL CENTRAL | Z184: 15 | AA184: LIMA | AB184: 1 | AC184: LIMA | AD184: 1 | AE184: LIMA
A185: 2018 | B185: GN | C185: GN | D185: 43462 | E185: 2018-2021 | F185: NO | G185: FORMULADO | H185: EMITIDO | P185: 43462 | Q185: 134-2018-CEPLANIDNCP-PEI | T185: 36 | U185: TRANSPORTES Y COMUNICACIONES | V185: 36 | W185: MINISTERIO DE TRANSPORTES Y COMUNICACIONES | X185: 1072 | Y185: MINISTERIO DE TRANSPORTES Y COMUNICACIONES-ADMINISTRACION GENERAL | Z185: 15 | AA185: LIMA | AB185: 1 | AC185: LIMA | AD185: 1 | AE185: LIMA
A186: 2018 | B186: MUN | C186: MD | D186: 43434 | E186: 2019-2022 | F186: NO | G186: FORMULADO | H186: EMITIDO | P186: 43434 | Q186: 092-2018-CEPLAN/DNCP-PEI | T186: 0 | U186: FICTICIO | V186: 300679 | W186: MUNICIPALIDAD DISTRITAL DE CARMEN DE LA LEGUA REYNOSO | X186: 300679 | Y186: MUNICIPALIDAD DISTRITAL DE CARMEN DE LA LEGUA REYNOSO | Z186: 7 | AA186: PROVINCIA CONSTITUCIONAL DEL CALLAO | AB186: 1 | AC186: PROV. CALLAO | AD186: 3 | AE186: CARMEN DE LA LEGUA REYNOSO
A187: 2018 | B187: MUN | C187: MD | D187: 43390 | E187: 2019-2022 | F187: NO | G187: FORMULADO | H187: EMITIDO | P187: 43390 | Q187: 077-2018-CEPLAN/DNCP-PEI | T187: 0 | U187: FICTICIO | V187: 300332 | W187: MUNICIPALIDAD DISTRITAL DE ALTO SELVA ALEGRE | X187: 300332 | Y187: MUNICIPALIDAD DISTRITAL DE ALTO SELVA ALEGRE | Z187: 4 | AA187: AREQUIPA | AB187: 1 | AC187: AREQUIPA | AD187: 2 | AE187: ALTO SELVA ALEGRE
A188: 2018 | B188: MUN | C188: MD | D188: 43236 | E188: 2018-2020 | F188: NO | G188: FORMULADO | H188: EMITIDO | P188: 43236 | Q188: 027-2018-CEPLAN/DNCP-PEI | T188: 0 | U188: FICTICIO | V188: 300786 | W188: MUNICIPALIDAD DISTRITAL DE CHINCHERO | X188: 300786 | Y188: MUNICIPALIDAD DISTRITAL DE CHINCHERO | Z188: 8 | AA188: CUSCO | AB188: 13 | AC188: URUBAMBA | AD188: 2 | AE188: CHINCHERO
A189: 2018 | B189: MUN | C189: MD | D189: 43453 | E189: 2019-2022 | F189: NO | G189: FORMULADO | H189: EMITIDO | P189: 43453 | Q189: 119-2018-CEPLAN/DNCP-PEI | T189: 0 | U189: FICTICIO | V189: 301258 | W189: MUNICIPALIDAD DISTRITAL DE CIENEGUILLA | X189: 301258 | Y189: MUNICIPALIDAD DISTRITAL DE CIENEGUILLA | Z189: 15 | AA189: LIMA | AB189: 1 | AC189: LIMA | AD189: 9 | AE189: CIENEGUILLA
A190: 2018 | B190: MUN | C190: MD | D190: 43416 | E190: 2019-2022 | F190: NO | G190: FORMULADO | H190: EMITIDO | P190: 43416 | Q190: 085-2018-CEPLAN/DNCP-PEI | T190: 0 | U190: FICTICIO | V190: 300749 | W190: MUNICIPALIDAD DISTRITAL DE ECHARATI | X190: 300749 | Y190: MUNICIPALIDAD DISTRITAL DE ECHARATI | Z190: 8 | AA190: CUSCO | AB190: 9 | AC190: LA CONVENCION | AD190: 2 | AE190: ECHARATI
A191: 2018 | B191: MUN | C191: MD | D191: 43225 | E191: 2018-2021 | F191: NO | G191: FORMULADO | H191: EMITIDO | P191: 43225 | Q191: 025-2018-CEPLAN/DNCP-PEI | T191: 0 | U191: FICTICIO | V191: 300874 | W191: MUNICIPALIDAD DISTRITAL DE HUACHOCOLPA | X191: 300874 | Y191: MUNICIPALIDAD DISTRITAL DE HUACHOCOLPA | Z191: 9 | AA191: HUANCAVELICA | AB191: 7 | AC191: TAYACAJA | AD191: 7 | AE191: HUACHOCOLPA
A192: 2018 | B192: MUN | C192: MD | D192: 43398 | E192: 2019-2022 | F192: NO | G192: FORMULADO | H192: EMITIDO | P192: 43398 | Q192: 082-2018-CEPLAN/DNCP-PEI | T192: 0 | U192: FICTICIO | V192: 301524 | W192: MUNICIPALIDAD DISTRITAL DE HUANCABAMBA | X192: 301524 | Y192: MUNICIPALIDAD DISTRITAL DE HUANCABAMBA | Z192: 19 | AA192: PASCO | AB192: 3 | AC192: OXAPAMPA | AD192: 3 | AE192: HUANCABAMBA
A193: 2018 | B193: MUN | C193: MD | D193: 43383 | E193: 2019-2021 | F193: NO | G193: FORMULADO | H193: EMITIDO | P193: 43383 | Q193: 073-2018-CEPLAN/DNCP-PEI | T193: 0 | U193: FICTICIO | V193: 300754 | W193: MUNICIPALIDAD DISTRITAL DE QUIMBIRI | X193: 300754 | Y193: MUNICIPALIDAD DISTRITAL DE QUIMBIRI | Z193: 8 | AA193: CUSCO | AB193: 9 | AC193: LA CONVENCION | AD193: 7 | AE193: QUIMBIRI
A194: 2018 | B194: MUN | C194: MD | D194: 43105 | E194: 2018-2020 | F194: NO | G194: FORMULADO | H194: EMITIDO | P194: 43105 | Q194: 002-2018-CEPLAN/DNCP-PEI | T194: 0 | U194: FICTICIO | V194: 301263 | W194: MUNICIPALIDAD DISTRITAL DE LA MOLINA | X194: 301263 | Y194: MUNICIPALIDAD DISTRITAL DE LA MOLINA | Z194: 15 | AA194: LIMA | AB194: 1 | AC194: LIMA | AD194: 14 | AE194: LA MOLINA
A195: 2018 | B195: MUN | C195: MD | D195: 43461 | E195: 2019-2021 | F195: NO | G195: FORMULADO | H195: EMITIDO | P195: 43461 | Q195: 132-2018-CEPLAN/DNCP-PEI | T195: 0 | U195: FICTICIO | V195: 300680 | W195: MUNICIPALIDAD DISTRITAL DE LA PERLA | X195: 300680 | Y195: MUNICIPALIDAD DISTRITAL DE LA PERLA | Z195: 7 | AA195: PROVINCIA CONSTITUCIONAL DEL CALLAO | AB195: 1 | AC195: PROV. CALLAO | AD195: 4 | AE195: LA PERLA
... A220: 2018 | B220: MUN | C220: MP | D220: 43440 | E220: 2019-2023 | F220: NO | G220: FORMULADO | H220: EMITIDO | P220: 43440 | Q220: 095-2018-CEPLAN/DNCP-PEI | T220: 0 | U220: FICTICIO | V220: 300022 | W220: MUNICIPALIDAD PROVINCIAL DE BAGUA | X220: 300022 | Y220: MUNICIPALIDAD PROVINCIAL DE BAGUA | Z220: 1 | AA220: AMAZONAS | AB220: 2 | AC220: BAGUA | AD220: 1 | AE220: BAGUA
A221: 2018 | B221: MUN | C221: MP | D221: 43341 | E221: 2019-2021 | F221: NO | G221: FORMULADO | H221: EMITIDO | I221: Filemon Sulca | P221: 43341 | Q221: 061-2018-CEPLAN/DNCP-PEI | T221: 0 | U221: FICTICIO | V221: 300724 | W221: MUNICIPALIDAD PROVINCIAL DE CANCHIS - SICUANI | X221: 300724 | Y221: MUNICIPALIDAD PROVINCIAL DE CANCHIS - SICUANI | Z221: 8 | AA221: CUSCO | AB221: 6 | AC221: CANCHIS | AD221: 1 | AE221: SICUANI
A222: 2018 | B222: MUN | C222: MP | D222: 43460 | E222: 2019-2022 | F222: NO | G222: FORMULADO | H222: EMITIDO | P222: 43460 | Q222: 123-2018-CEPLAN/DNCP-PEI | T222: 0 | U222: FICTICIO | V222: 301623 | W222: MUNICIPALIDAD PROVINCIAL DE CARABAYA - MACUSANI | X222: 301623 | Y222: MUNICIPALIDAD PROVINCIAL DE CARABAYA - MACUSANI | Z222: 21 | AA222: PUNO | AB222: 3 | AC222: CARABAYA | AD222: 1 | AE222: MACUSANI
A223: 2018 | B223: MUN | C223: MP | D223: 43215 | E223: 2019-2021 | F223: NO | G223: FORMULADO | H223: EMITIDO | P223: 43215 | Q223: 023-2018-CEPLAN/DNCP-PEI | T223: 0 | U223: FICTICIO | V223: 300125 | W223: MUNICIPALIDAD PROVINCIAL DE CARHUAZ | X223: 300125 | Y223: MUNICIPALIDAD PROVINCIAL DE CARHUAZ | Z223: 2 | AA223: ANCASH | AB223: 6 | AC223: CARHUAZ | AD223: 1 | AE223: CARHUAZ
A224: 2018 | B224: MUN | C224: MP | D224: 43357 | E224: 2019-2021 | F224: NO | G224: FORMULADO | H224: EMITIDO | P224: 43357 | Q224: 067-2018-CEPLAN/DNCP-PEI | T224: 0 | U224: FICTICIO | V224: 300829 | W224: MUNICIPALIDAD PROVINCIAL DE CASTROVIRREYNA | X224: 300829 | Y224: MUNICIPALIDAD PROVINCIAL DE CASTROVIRREYNA | Z224: 9 | AA224: HUANCAVELICA | AB224: 4 | AC224: CASTROVIRREYNA | AD224: 1 | AE224: CASTROVIRREYNA
A225: 2018 | B225: MUN | C225: MP | D225: 43263 | E225: 2019-2021 | F225: NO | G225: FORMULADO | H225: EMITIDO | P225: 43263 | Q225: 040-2018-CEPLAN/DNCP-PEI | T225: 0 | U225: FICTICIO | V225: 300001 | W225: MUNICIPALIDAD PROVINCIAL DE CHACHAPOYAS | X225: 300001 | Y225: MUNICIPALIDAD PROVINCIAL DE CHACHAPOYAS | Z225: 1 | AA225: AMAZONAS | AB225: 1 | AC225: CHACHAPOYAS | AD225: 1 | AE225: CHACHAPOYAS
A226: 2018 | B226: MUN | C226: MP | D226: 43430 | E226: 2019-2021 | F226: NO | G226: FORMULADO | H226: EMITIDO | P226: 43430 | Q226: 091-2018-CEPLAN/DNCP-PEI | T226: 0 | U226: FICTICIO | V226: 300842 | W226: MUNICIPALIDAD PROVINCIAL DE CHURCAMPA | X226: 300842 | Y226: MUNICIPALIDAD PROVINCIAL DE CHURCAMPA | Z226: 9 | AA226: HUANCAVELICA | AB226: 5 | AC226: CHURCAMPA | AD226: 1 | AE226: CHURCAMPA
A227: 2018 | B227: MUN | C227: MP | D227: 43461 | E227: 2019-2022 | F227: NO | G227: FORMULADO | H227: EMITIDO | P227: 43461 | Q227: 129-2018-CEPLAN/DNCP-PEI | T227: 0 | U227: FICTICIO | V227: 300040 | W227: MUNICIPALIDAD PROVINCIAL DE CONDORCANQUI - NIEVA | X227: 300040 | Y227: MUNICIPALIDAD PROVINCIAL DE CONDORCANQUI - NIEVA | Z227: 1 | AA227: AMAZONAS | AB227: 4 | AC227: CONDORCANQUI | AD227: 1 | AE227: NIEVA
A228: 2018 | B228: MUN | C228: MP | D228: 43391 | E228: 2019-2021 | F228: NO | G228: FORMULADO | H228: EMITIDO | P228: 43391 | Q228: 078-2018-CEPLAN/DNCP-PEI | T228: 0 | U228: FICTICIO | V228: 300740 | W228: MUNICIPALIDAD PROVINCIAL DE ESPINAR | X228: 300740 | Y228: MUNICIPALIDAD PROVINCIAL DE ESPINAR | Z228: 8 | AA228: CUSCO | AB228: 8 | AC228: ESPINAR | AD228: 1 | AE228: ESPINAR
A229: 2018 | B229: MUN | C229: MP | D229: 43301 | E229: 2019-2021 | F229: NO | G229: FORMULADO | H229: EMITIDO | P229: 43301 | Q229: 049-2018-CEPLAN/DNCP-PEI | T229: 0 | U229: FICTICIO | V229: 301232 | W229: MUNICIPALIDAD PROVINCIAL DE FERREÑAFE | X229: 301232 | Y229: MUNICIPALIDAD PROVINCIAL DE FERREÑAFE | Z229: 14 | AA229: LAMBAYEQUE | AB229: 2 | AC229: FERRENAFE | AD229: 1 | AE229: FERRENAFE
A230: 2018 | B230: MUN | C230: MP | D230: 43453 | E230: 2019-2022 | F230: NO | G230: FORMULADO | H230: EMITIDO | I230: Leidy Cayotopa / Ivan PNUD | P230: 43453 | Q230: 116-2018-CEPLAN/DNCP-PEI | T230: 0 | U230: FICTICIO | V230: 300916 | W230: MUNICIPALIDAD PROVINCIAL DE HUAMALIES - LLATA | X230: 300916 | Y230: MUNICIPALIDAD PROVINCIAL DE HUAMALIES - LLATA | Z230: 10 | AA230: HUANUCO | AB230: 5 | AC230: HUAMALIES | AD230: 1 | AE230: LLATA
A231: 2018 | B231: MUN | C231: MP | D231: 43311 | E231: 2019-2021 | F231: NO | G231: FORMULADO | H231: EMITIDO | P231: 43311 | Q231: 056-2018-CEPLAN/DNCP-PEI | T231: 0 | U231: FICTICIO | V231: 300460 | W231: MUNICIPALIDAD PROVINCIAL DE HUANCA SANCOS - SANCOS | X231: 300460 | Y231: MUNICIPALIDAD PROVINCIAL DE HUANCA SANCOS - SANCOS | Z231: 5 | AA231: AYACUCHO | AB231: 3 | AC231: HUANCA SANCOS | AD231: 1 | AE231: SANCOS
...

Sheet Data_UEs
A1: NG | B1: NG1 | C1: NivelGobierno | D1: Id_Sector | E1: nombre_sector | F1: Id_Pliego | G1: nombre_pliego | H1: Id_UE | I1: Nombre_unidad_ejecutora | J1: Id_Departamento | K1: nombre_departamento | L1: Id_Provincia | M1: nombre_provincia | N1: Id_4Distrito | O1: nombre_distrito | P1: TipoDistrito | Q1: PEI | R1: POI | S1: PESEM | T1: PDC | U1: Universidad? | V1: OtroTipoEntidad | W1: c/ PEI | X1: Ult.PEI | Y1: Tipo PEI | Z1: PEI_vigente? | AA1: Estado_PEI | AB1: Expediente | AC1: Fecha de Informe Técnico | AD1: Nro de Informe Técnico | AE1: PEI al 2030? | AF1: Vigente 2030 | AG1: No vigente al 2030 | AH1: EnProceso-Vigente 2030 | AI1: ¿ACTIVO? | AJ1: Responsable Institucional | AK1: Correo electrónico | AL1: Operador planeamiento_UE | AM1: Cargo (Según ROF) | AN1: Número de contacto | AO1: Correo electrónico | AP1: POI 2022 (Seguimiento) | AQ1: POI 2023-2025 (Aprobado) | AR1: POI 2024-2026 (Elaborado) | AS1: POI 2024-2026 (Aprobado) | AT1: POI 2024-2026 (Ajustado) | AU1: POI 2024-2026 (Consistenciado) | AV1: POI 2024-2026 (Estado Cons) | AW1: POI 2024 (Seguimiento ) | AX1: POI 2025-2027 (Elaborado) | AY1: POI 2025-2027 (Aprobado) | AZ1: POI 2025-2027 (Ajustado) | BA1: POI 2025-2027 (Consistenciado) | BB1: POI 2025-2027 (Estado Consistenciado) | BC1: POI 2025-2027 (Estado Seguimiento) | BD1: POI 2026-2028 (Elab) | BE1: POI 2026-2028 (Aprob) | BF1: POI 2026-2028 (Ajustado) | BG1: POI 2026-2028 (Consistenciado) | BH1: POI 2026-2028 (Estado Consistenciado) | BI1: POI 2026 (Seguimiento) | BJ1: POI 2027-2029 (Elab) | BK1: POI 2027-2029 (Aprob) | BL1: SUMA_APROBADO_2026 | BM1: SUMA_ELABORACION_2027 | BN1: SUMA_APROBADO_2027 | BO1: SUMA_ELABORACION_2028 | BP1: SUMA_APROBADO_2028 | BQ1: Tiene_PDC? | BR1: Periodo PDC | BS1: PDC_Aprobado? | BT1: PDC_vigente?
A2: Gobierno nacional | B2: OCA | C2: E | D2: 4 | E2: PODER JUDICIAL | F2: 40 | G2: ACADEMIA DE LA MAGISTRATURA | H2: 14 | I2: ACADEMIA DE LA MAGISTRATURA | J2: 15 | K2: LIMA | L2: 1 | M2: LIMA | N2: 1 | O2: LIMA | Q2: S | R2: S | V2: OCA | W2: =IFERROR(VLOOKUP(H2,'IT PEI'!$X$2:$X$5647,1,0),"...") -> 14 | X2: =_xlfn.XLOOKUP(H2,'IT PEI'!X$2:X$5647,'IT PEI'!E$2:E$5647,"...",2,-1) -> 2024-2030 | Y2: =_xlfn.XLOOKUP(H2,'IT PEI'!X$2:X$5647,'IT PEI'!G$2:G$5647,"...",2,-1) -> FORMULADO | Z2: =_xlfn.XLOOKUP(H2,'IT PEI'!X$2:X$5647,'IT PEI'!F$2:F$5647,"...",2,-1) -> SI | AA2: =_xlfn.XLOOKUP(H2,'IT PEI'!X$2:X$5647,'IT PEI'!H$2:H$5647,"...",2,-1) -> EMITIDO | AB2: =_xlfn.XLOOKUP(H2,'IT PEI'!X$2:X$5647,'IT PEI'!O$2:O$5647,"...",2,-1) -> 2024-0000196 | AC2: =_xlfn.XLOOKUP(H2,'IT PEI'!X$2:X$5647,'IT PEI'!P$2:P$5647,"...",2,-1) -> 45310 | AD2: =_xlfn.XLOOKUP(H2,'IT PEI'!X$2:X$5647,'IT PEI'!Q$2:Q$5647,"...",2,-1) -> 000009-2024-CEPLAN-DNCPPEI | AE2: =IF(COUNTIF(X2, "*" & "2030" & "*")>0, "SI", "No" ) -> SI | AF2: =IF(COUNTIF(X2, "*" & "2030" & "*")>0, 1, 0 ) -> 1 | AG2: =IF(COUNTIF(X2, "*" & "2030" & "*")>0, 0, 1 ) -> 0 | AH2: =IF(AND(AA2="En Proceso",AE2="Si"),1,0) -> 0 | AI2: ACTIVO | AJ2: Addy López Peña | AK2: alopez@ceplan.gob.pe | AL2: =IFERROR(VLOOKUP(tbl_ues[[#This Row],[Id_UE]],'[1]Directorio v.02'!$H$3:$U$3089,11,FALSE),"") -> Miguel Angel Dávila Servat | AM2: =IFERROR(VLOOKUP(tbl_ues[[#This Row],[Id_UE]],'[1]Directorio v.02'!$H$3:$U$3089,12,FALSE),"") -> Jefe de la Oficina de Planificación y Presupuesto | AN2: =IFERROR(VLOOKUP(tbl_ues[[#This Row],[Id_UE]],'[1]Directorio v.02'!$H$3:$U$3089,13,FALSE),"") -> 4280300 anx 524 | AO2: =IFERROR(VLOOKUP(tbl_ues[[#This Row],[Id_UE]],'[1]Directorio v.02'!$H$3:$U$3089,14,FALSE),"") -> mdavila@amag.edu.pe | AP2: =VLOOKUP(H2,#REF!,7,0) -> #REF! | AQ2: =VLOOKUP(H2,#REF!,9,0) -> #REF! | AR2: =VLOOKUP(H2,#REF!,15,0) -> #REF! | AS2: =VLOOKUP(H2,#REF!,16,0) -> #REF! | AT2: =VLOOKUP(H2,#REF!,17,0) -> #REF! | AU2: =VLOOKUP(H2,#REF!,18,0) -> #REF! | AV2: =VLOOKUP(H2,#REF!,19,0) -> #REF! | AW2: =VLOOKUP(H2,#REF!,20,0) -> #REF! | AX2: =VLOOKUP(H2,#REF!,22,0) -> #REF! | AY2: =VLOOKUP(H2,#REF!,23,0) -> #REF! | AZ2: =VLOOKUP(H2,#REF!,24,0) -> #REF! | BA2: =VLOOKUP(H2,#REF!,25,0) -> #REF! | BB2: =VLOOKUP(H2,#REF!,26,0) -> #REF! | BC2: =VLOOKUP(H2,#REF!,27,0) -> #REF! | BD2: =VLOOKUP(H2,#REF!,29,0) -> #REF! | BE2: =VLOOKUP(H2,#REF!,30,0) -> #REF! | BF2: =VLOOKUP(H2,#REF!,31,0) -> #REF! | BG2: =VLOOKUP(H2,#REF!,32,0) -> #REF! | BH2: =VLOOKUP(H2,#REF!,33,0) -> #REF! | BI2: =VLOOKUP(H2,#REF!,34,0) -> #REF! | BJ2: =VLOOKUP(H2,#REF!,36,0) -> #REF! | BK2: =VLOOKUP(H2,#REF!,37,0) -> #REF! | BL2: =VLOOKUP(H2,#REF!,44,0) -> #REF! | BM2: =VLOOKUP(H2,#REF!,45,0) -> #REF! | BN2: =VLOOKUP(H2,#REF!,46,0) -> #REF! | BO2: =VLOOKUP(H2,#REF!,47,0) -> #REF! | BP2: =VLOOKUP(H2,#REF!,48,0) -> #REF!
A3: Gobierno nacional | B3: Poder Ejecutivo | C3: E | D3: 26 | E3: DEFENSA | F3: 335 | G3: AGENCIA DE COMPRAS DE LAS FUERZAS ARMADAS | H3: 1545 | I3: AGENCIA DE COMPRAS DE LAS FUERZAS ARMADAS | J3: 15 | K3: LIMA | L3: 1 | M3: LIMA | N3: 1 | O3: LIMA | Q3: S | R3: S | W3: =IFERROR(VLOOKUP(H3,'IT PEI'!$X$2:$X$5647,1,0),"...") -> 1545 | X3: =_xlfn.XLOOKUP(H3,'IT PEI'!X$2:X$5647,'IT PEI'!E$2:E$5647,"...",2,-1) -> 2025-2030 | Y3: =_xlfn.XLOOKUP(H3,'IT PEI'!X$2:X$5647,'IT PEI'!G$2:G$5647,"...",2,-1) -> FORMULADO | Z3: =_xlfn.XLOOKUP(H3,'IT PEI'!X$2:X$5647,'IT PEI'!F$2:F$5647,"...",2,-1) -> SI | AA3: =_xlfn.XLOOKUP(H3,'IT PEI'!X$2:X$5647,'IT PEI'!H$2:H$5647,"...",2,-1) -> EMITIDO | AB3: =_xlfn.XLOOKUP(H3,'IT PEI'!X$2:X$5647,'IT PEI'!O$2:O$5647,"...",2,-1) -> 2025-000382 | AC3: =_xlfn.XLOOKUP(H3,'IT PEI'!X$2:X$5647,'IT PEI'!P$2:P$5647,"...",2,-1) -> 45688 | AD3: =_xlfn.XLOOKUP(H3,'IT PEI'!X$2:X$5647,'IT PEI'!Q$2:Q$5647,"...",2,-1) -> 000039-2025-CEPLAN-DNCPPEI | AE3: =IF(COUNTIF(X3, "*" & "2030" & "*")>0, "SI", "No" ) -> SI | AF3: =IF(COUNTIF(X3, "*" & "2030" & "*")>0, 1, 0 ) -> 1 | AG3: =IF(COUNTIF(X3, "*" & "2030" & "*")>0, 0, 1 ) -> 0 | AH3: =IF(AND(AA3="En Proceso",AE3="Si"),1,0) -> 0 | AI3: ACTIVO | AJ3: Leidy Cayotopa Mesones | AK3: leidy.cayotopa.ceplan@gmail.com | AL3: =IFERROR(VLOOKUP(tbl_ues[[#This Row],[Id_UE]],'[1]Directorio v.02'!$H$3:$U$3089,11,FALSE),"") -> Francisco José Ríos Lituma | AM3: =IFERROR(VLOOKUP(tbl_ues[[#This Row],[Id_UE]],'[1]Directorio v.02'!$H$3:$U$3089,12,FALSE),"") -> Jefe de la Oficina de Planeamiento y Presupuesto | AN3: =IFERROR(VLOOKUP(tbl_ues[[#This Row],[Id_UE]],'[1]Directorio v.02'!$H$3:$U$3089,13,FALSE),"") -> 206-0100 Anexo 2140 | AO3: =IFERROR(VLOOKUP(tbl_ues[[#This Row],[Id_UE]],'[1]Directorio v.02'!$H$3:$U$3089,14,FALSE),"") -> francisco.rios@acffaa.gob.pe | AP3: =VLOOKUP(H3,#REF!,7,0) -> #REF! | AQ3: =VLOOKUP(H3,#REF!,9,0) -> #REF! | AR3: =VLOOKUP(H3,#REF!,15,0) -> #REF! | AS3: =VLOOKUP(H3,#REF!,16,0) -> #REF! | AT3: =VLOOKUP(H3,#REF!,17,0) -> #REF! | AU3: =VLOOKUP(H3,#REF!,18,0) -> #REF! | AV3: =VLOOKUP(H3,#REF!,19,0) -> #REF! | AW3: =VLOOKUP(H3,#REF!,20,0) -> #REF! | AX3: =VLOOKUP(H3,#REF!,22,0) -> #REF! | AY3: =VLOOKUP(H3,#REF!,23,0) -> #REF! | AZ3: =VLOOKUP(H3,#REF!,24,0) -> #REF! | BA3: =VLOOKUP(H3,#REF!,25,0) -> #REF! | BB3: =VLOOKUP(H3,#REF!,26,0) -> #REF! | BC3: =VLOOKUP(H3,#REF!,27,0) -> #REF! | BD3: =VLOOKUP(H3,#REF!,29,0) -> #REF! | BE3: =VLOOKUP(H3,#REF!,30,0) -> #REF! | BF3: =VLOOKUP(H3,#REF!,31,0) -> #REF! | BG3: =VLOOKUP(H3,#REF!,32,0) -> #REF! | BH3: =VLOOKUP(H3,#REF!,33,0) -> #REF! | BI3: =VLOOKUP(H3,#REF!,34,0) -> #REF! | BJ3: =VLOOKUP(H3,#REF!,36,0) -> #REF! | BK3: =VLOOKUP(H3,#REF!,37,0) -> #REF! | BL3: =VLOOKUP(H3,#REF!,44,0) -> #REF! | BM3: =VLOOKUP(H3,#REF!,45,0) -> #REF! | BN3: =VLOOKUP(H3,#REF!,46,0) -> #REF! | BO3: =VLOOKUP(H3,#REF!,47,0) -> #REF! | BP3: =VLOOKUP(H3,#REF!,48,0) -> #REF!
A4: Gobierno nacional | B4: Poder Ejecutivo | C4: E | D4: 9 | E4: ECONOMIA Y FINANZAS | F4: 55 | G4: AGENCIA DE PROMOCION DE LA INVERSION PRIVADA | H4: 1231 | I4: AGENCIA DE PROMOCION DE LA INVERSION PRIVADA - PROINVERSION | J4: 15 | K4: LIMA | L4: 1 | M4: LIMA | N4: 31 | O4: SAN ISIDRO | Q4: S | R4: S | W4: =IFERROR(VLOOKUP(H4,'IT PEI'!$X$2:$X$5647,1,0),"...") -> 1231 | X4: =_xlfn.XLOOKUP(H4,'IT PEI'!X$2:X$5647,'IT PEI'!E$2:E$5647,"...",2,-1) -> 2024-2030 | Y4: =_xlfn.XLOOKUP(H4,'IT PEI'!X$2:X$5647,'IT PEI'!G$2:G$5647,"...",2,-1) -> FORMULADO | Z4: =_xlfn.XLOOKUP(H4,'IT PEI'!X$2:X$5647,'IT PEI'!F$2:F$5647,"...",2,-1) -> SI | AA4: =_xlfn.XLOOKUP(H4,'IT PEI'!X$2:X$5647,'IT PEI'!H$2:H$5647,"...",2,-1) -> EMITIDO | AB4: =_xlfn.XLOOKUP(H4,'IT PEI'!X$2:X$5647,'IT PEI'!O$2:O$5647,"...",2,-1) -> 2024-0001603 | AC4: =_xlfn.XLOOKUP(H4,'IT PEI'!X$2:X$5647,'IT PEI'!P$2:P$5647,"...",2,-1) -> 45433 | AD4: =_xlfn.XLOOKUP(H4,'IT PEI'!X$2:X$5647,'IT PEI'!Q$2:Q$5647,"...",2,-1) -> 000238-2024-CEPLAN-DNCPPEI | AE4: =IF(COUNTIF(X4, "*" & "2030" & "*")>0, "SI", "No" ) -> SI | AF4: =IF(COUNTIF(X4, "*" & "2030" & "*")>0, 1, 0 ) -> 1 | AG4: =IF(COUNTIF(X4, "*" & "2030" & "*")>0, 0, 1 ) -> 0 | AH4: =IF(AND(AA4="En Proceso",AE4="Si"),1,0) -> 0 | AI4: ACTIVO | AJ4: Fatima Amoretti Arteaga | AK4: fatima.amoretti.ceplan@gmail.com | AL4: =IFERROR(VLOOKUP(tbl_ues[[#This Row],[Id_UE]],'[1]Directorio v.02'!$H$3:$U$3089,11,FALSE),"") -> Apolinar Madrid Escobar | AM4: =IFERROR(VLOOKUP(tbl_ues[[#This Row],[Id_UE]],'[1]Directorio v.02'!$H$3:$U$3089,12,FALSE),"") -> Jefe de la Oficina de Planeamiento y Presupuesto € | AN4: =IFERROR(VLOOKUP(tbl_ues[[#This Row],[Id_UE]],'[1]Directorio v.02'!$H$3:$U$3089,13,FALSE),"") -> 2001200 A.1353 | AO4: =IFERROR(VLOOKUP(tbl_ues[[#This Row],[Id_UE]],'[1]Directorio v.02'!$H$3:$U$3089,14,FALSE),"") -> amadrid@proinversion.gob.pe | AP4: =VLOOKUP(H4,#REF!,7,0) -> #REF! | AQ4: =VLOOKUP(H4,#REF!,9,0) -> #REF! | AR4: =VLOOKUP(H4,#REF!,15,0) -> #REF! | AS4: =VLOOKUP(H4,#REF!,16,0) -> #REF! | AT4: =VLOOKUP(H4,#REF!,17,0) -> #REF! | AU4: =VLOOKUP(H4,#REF!,18,0) -> #REF! | AV4: =VLOOKUP(H4,#REF!,19,0) -> #REF! | AW4: =VLOOKUP(H4,#REF!,20,0) -> #REF! | AX4: =VLOOKUP(H4,#REF!,22,0) -> #REF! | AY4: =VLOOKUP(H4,#REF!,23,0) -> #REF! | AZ4: =VLOOKUP(H4,#REF!,24,0) -> #REF! | BA4: =VLOOKUP(H4,#REF!,25,0) -> #REF! | BB4: =VLOOKUP(H4,#REF!,26,0) -> #REF! | BC4: =VLOOKUP(H4,#REF!,27,0) -> #REF! | BD4: =VLOOKUP(H4,#REF!,29,0) -> #REF! | BE4: =VLOOKUP(H4,#REF!,30,0) -> #REF! | BF4: =VLOOKUP(H4,#REF!,31,0) -> #REF! | BG4: =VLOOKUP(H4,#REF!,32,0) -> #REF! | BH4: =VLOOKUP(H4,#REF!,33,0) -> #REF! | BI4: =VLOOKUP(H4,#REF!,34,0) -> #REF! | BJ4: =VLOOKUP(H4,#REF!,36,0) -> #REF! | BK4: =VLOOKUP(H4,#REF!,37,0) -> #REF! | BL4: =VLOOKUP(H4,#REF!,44,0) -> #REF! | BM4: =VLOOKUP(H4,#REF!,45,0) -> #REF! | BN4: =VLOOKUP(H4,#REF!,46,0) -> #REF! | BO4: =VLOOKUP(H4,#REF!,47,0) -> #REF! | BP4: =VLOOKUP(H4,#REF!,48,0) -> #REF!
A5: Gobierno nacional | B5: Poder Ejecutivo | C5: E | D5: 8 | E5: RELACIONES EXTERIORES | F5: 80 | G5: AGENCIA PERUANA DE COOPERACION INTERNACIONAL - APCI | H5: 1089 | I5: AGENCIA PERUANA DE COOPERACION INTERNACIONAL - APCI | J5: 15 | K5: LIMA | L5: 1 | M5: LIMA | N5: 22 | O5: MIRAFLORES | Q5: S | R5: S | W5: =IFERROR(VLOOKUP(H5,'IT PEI'!$X$2:$X$5647,1,0),"...") -> 1089 | X5: =_xlfn.XLOOKUP(H5,'IT PEI'!X$2:X$5647,'IT PEI'!E$2:E$5647,"...",2,-1) -> 2025-2030 | Y5: =_xlfn.XLOOKUP(H5,'IT PEI'!X$2:X$5647,'IT PEI'!G$2:G$5647,"...",2,-1) -> MODIFICADO | Z5: =_xlfn.XLOOKUP(H5,'IT PEI'!X$2:X$5647,'IT PEI'!F$2:F$5647,"...",2,-1) -> SI | AA5: =_xlfn.XLOOKUP(H5,'IT PEI'!X$2:X$5647,'IT PEI'!H$2:H$5647,"...",2,-1) -> EN PROCESO | AB5: =_xlfn.XLOOKUP(H5,'IT PEI'!X$2:X$5647,'IT PEI'!O$2:O$5647,"...",2,-1) -> 0 | AC5: =_xlfn.XLOOKUP(H5,'IT PEI'!X$2:X$5647,'IT PEI'!P$2:P$5647,"...",2,-1) -> 0 | AD5: =_xlfn.XLOOKUP(H5,'IT PEI'!X$2:X$5647,'IT PEI'!Q$2:Q$5647,"...",2,-1) -> 0 | AE5: =IF(COUNTIF(X5, "*" & "2030" & "*")>0, "SI", "No" ) -> SI | AF5: =IF(COUNTIF(X5, "*" & "2030" & "*")>0, 1, 0 ) -> 1 | AG5: =IF(COUNTIF(X5, "*" & "2030" & "*")>0, 0, 1 ) -> 0 | AH5: =IF(AND(AA5="En Proceso",AE5="Si"),1,0) -> 1 | AI5: ACTIVO | AJ5: Vilma Celestino Villafana | AK5: vcelestinov@gmail.com | AL5: =IFERROR(VLOOKUP(tbl_ues[[#This Row],[Id_UE]],'[1]Directorio v.02'!$H$3:$U$3089,11,FALSE),"") -> Ing. Cesar Eduardo Díaz Díaz | AM5: =IFERROR(VLOOKUP(tbl_ues[[#This Row],[Id_UE]],'[1]Directorio v.02'!$H$3:$U$3089,12,FALSE),"") -> Jefe de la Oficina de Planeamiento y Presupuesto | AN5: =IFERROR(VLOOKUP(tbl_ues[[#This Row],[Id_UE]],'[1]Directorio v.02'!$H$3:$U$3089,13,FALSE),"") -> 944 266 341 | AO5: =IFERROR(VLOOKUP(tbl_ues[[#This Row],[Id_UE]],'[1]Directorio v.02'!$H$3:$U$3089,14,FALSE),"") -> cdiaz@apci.gob.pe | AP5: =VLOOKUP(H5,#REF!,7,0) -> #REF! | AQ5: =VLOOKUP(H5,#REF!,9,0) -> #REF! | AR5: =VLOOKUP(H5,#REF!,15,0) -> #REF! | AS5: =VLOOKUP(H5,#REF!,16,0) -> #REF! | AT5: =VLOOKUP(H5,#REF!,17,0) -> #REF! | AU5: =VLOOKUP(H5,#REF!,18,0) -> #REF! | AV5: =VLOOKUP(H5,#REF!,19,0) -> #REF! | AW5: =VLOOKUP(H5,#REF!,20,0) -> #REF! | AX5: =VLOOKUP(H5,#REF!,22,0) -> #REF! | AY5: =VLOOKUP(H5,#REF!,23,0) -> #REF! | AZ5: =VLOOKUP(H5,#REF!,24,0) -> #REF! | BA5: =VLOOKUP(H5,#REF!,25,0) -> #REF! | BB5: =VLOOKUP(H5,#REF!,26,0) -> #REF! | BC5: =VLOOKUP(H5,#REF!,27,0) -> #REF! | BD5: =VLOOKUP(H5,#REF!,29,0) -> #REF! | BE5: =VLOOKUP(H5,#REF!,30,0) -> #REF! | BF5: =VLOOKUP(H5,#REF!,31,0) -> #REF! | BG5: =VLOOKUP(H5,#REF!,32,0) -> #REF! | BH5: =VLOOKUP(H5,#REF!,33,0) -> #REF! | BI5: =VLOOKUP(H5,#REF!,34,0) -> #REF! | BJ5: =VLOOKUP(H5,#REF!,36,0) -> #REF! | BK5: =VLOOKUP(H5,#REF!,37,0) -> #REF! | BL5: =VLOOKUP(H5,#REF!,44,0) -> #REF! | BM5: =VLOOKUP(H5,#REF!,45,0) -> #REF! | BN5: =VLOOKUP(H5,#REF!,46,0) -> #REF! | BO5: =VLOOKUP(H5,#REF!,47,0) -> #REF! | BP5: =VLOOKUP(H5,#REF!,48,0) -> #REF!
A6: Gobierno nacional | B6: Poder Ejecutivo | C6: E | D6: 3 | E6: CULTURA | F6: 60 | G6: ARCHIVO GENERAL DE LA NACION | H6: 16 | I6: OFICINA TECNICA ADMINISTRATIVA-ARCHIVO GENERAL DE LA NACION | J6: 15 | K6: LIMA | L6: 1 | M6: LIMA | N6: 1 | O6: LIMA | Q6: S | R6: S | W6: =IFERROR(VLOOKUP(H6,'IT PEI'!$X$2:$X$5647,1,0),"...") -> 16 | X6: =_xlfn.XLOOKUP(H6,'IT PEI'!X$2:X$5647,'IT PEI'!E$2:E$5647,"...",2,-1) -> 2025-2030 | Y6: =_xlfn.XLOOKUP(H6,'IT PEI'!X$2:X$5647,'IT PEI'!G$2:G$5647,"...",2,-1) -> FORMULADO | Z6: =_xlfn.XLOOKUP(H6,'IT PEI'!X$2:X$5647,'IT PEI'!F$2:F$5647,"...",2,-1) -> SI | AA6: =_xlfn.XLOOKUP(H6,'IT PEI'!X$2:X$5647,'IT PEI'!H$2:H$5647,"...",2,-1) -> EMITIDO | AB6: =_xlfn.XLOOKUP(H6,'IT PEI'!X$2:X$5647,'IT PEI'!O$2:O$5647,"...",2,-1) -> 2025-0000332 | AC6: =_xlfn.XLOOKUP(H6,'IT PEI'!X$2:X$5647,'IT PEI'!P$2:P$5647,"...",2,-1) -> 45687 | AD6: =_xlfn.XLOOKUP(H6,'IT PEI'!X$2:X$5647,'IT PEI'!Q$2:Q$5647,"...",2,-1) -> 000032-2025-CEPLAN-DNCPPEI | AE6: =IF(COUNTIF(X6, "*" & "2030" & "*")>0, "SI", "No" ) -> SI | AF6: =IF(COUNTIF(X6, "*" & "2030" & "*")>0, 1, 0 ) -> 1 | AG6: =IF(COUNTIF(X6, "*" & "2030" & "*")>0, 0, 1 ) -> 0 | AH6: =IF(AND(AA6="En Proceso",AE6="Si"),1,0) -> 0 | AI6: ACTIVO | AJ6: Lourdes Gutierrez Aguado | AK6: lgutierrez@ceplan.gob.pe | AL6: =IFERROR(VLOOKUP(tbl_ues[[#This Row],[Id_UE]],'[1]Directorio v.02'!$H$3:$U$3089,11,FALSE),"") -> Carlos Ricardo Velazco Bonzano | AM6: =IFERROR(VLOOKUP(tbl_ues[[#This Row],[Id_UE]],'[1]Directorio v.02'!$H$3:$U$3089,12,FALSE),"") -> Jefe de la Oficina de Planeamiento y Presupuesto | AN6: =IFERROR(VLOOKUP(tbl_ues[[#This Row],[Id_UE]],'[1]Directorio v.02'!$H$3:$U$3089,13,FALSE),"") -> 426-7221 - Anexo: 222 | AO6: =IFERROR(VLOOKUP(tbl_ues[[#This Row],[Id_UE]],'[1]Directorio v.02'!$H$3:$U$3089,14,FALSE),"") -> cvelazco@agn.gob.pe | AP6: =VLOOKUP(H6,#REF!,7,0) -> #REF! | AQ6: =VLOOKUP(H6,#REF!,9,0) -> #REF! | AR6: =VLOOKUP(H6,#REF!,15,0) -> #REF! | AS6: =VLOOKUP(H6,#REF!,16,0) -> #REF! | AT6: =VLOOKUP(H6,#REF!,17,0) -> #REF! | AU6: =VLOOKUP(H6,#REF!,18,0) -> #REF! | AV6: =VLOOKUP(H6,#REF!,19,0) -> #REF! | AW6: =VLOOKUP(H6,#REF!,20,0) -> #REF! | AX6: =VLOOKUP(H6,#REF!,22,0) -> #REF! | AY6: =VLOOKUP(H6,#REF!,23,0) -> #REF! | AZ6: =VLOOKUP(H6,#REF!,24,0) -> #REF! | BA6: =VLOOKUP(H6,#REF!,25,0) -> #REF! | BB6: =VLOOKUP(H6,#REF!,26,0) -> #REF! | BC6: =VLOOKUP(H6,#REF!,27,0) -> #REF! | BD6: =VLOOKUP(H6,#REF!,29,0) -> #REF! | BE6: =VLOOKUP(H6,#REF!,30,0) -> #REF! | BF6: =VLOOKUP(H6,#REF!,31,0) -> #REF! | BG6: =VLOOKUP(H6,#REF!,32,0) -> #REF! | BH6: =VLOOKUP(H6,#REF!,33,0) -> #REF! | BI6: =VLOOKUP(H6,#REF!,34,0) -> #REF! | BJ6: =VLOOKUP(H6,#REF!,36,0) -> #REF! | BK6: =VLOOKUP(H6,#REF!,37,0) -> #REF! | BL6: =VLOOKUP(H6,#REF!,44,0) -> #REF! | BM6: =VLOOKUP(H6,#REF!,45,0) -> #REF! | BN6: =VLOOKUP(H6,#REF!,46,0) -> #REF! | BO6: =VLOOKUP(H6,#REF!,47,0) -> #REF! | BP6: =VLOOKUP(H6,#REF!,48,0) -> #REF!
A7: Gobierno nacional | B7: Poder Ejecutivo | C7: E | D7: 36 | E7: TRANSPORTES Y COMUNICACIONES | F7: 203 | G7: AUTORIDAD DE TRANSPORTE URBANO PARA LIMA Y CALLAO - ATU | H7: 1717 | I7: AUTORIDAD DE TRANSPORTE URBANO PARA LIMA Y CALLAO - ATU | J7: 15 | K7: LIMA | L7: 1 | M7: LIMA | N7: 22 | O7: MIRAFLORES | Q7: S | R7: S | W7: =IFERROR(VLOOKUP(H7,'IT PEI'!$X$2:$X$5647,1,0),"...") -> 1717 | X7: =_xlfn.XLOOKUP(H7,'IT PEI'!X$2:X$5647,'IT PEI'!E$2:E$5647,"...",2,-1) -> 2024-2030 | Y7: =_xlfn.XLOOKUP(H7,'IT PEI'!X$2:X$5647,'IT PEI'!G$2:G$5647,"...",2,-1) -> ACTUALIZADO | Z7: =_xlfn.XLOOKUP(H7,'IT PEI'!X$2:X$5647,'IT PEI'!F$2:F$5647,"...",2,-1) -> SI | AA7: =_xlfn.XLOOKUP(H7,'IT PEI'!X$2:X$5647,'IT PEI'!H$2:H$5647,"...",2,-1) -> EMITIDO | AB7: =_xlfn.XLOOKUP(H7,'IT PEI'!X$2:X$5647,'IT PEI'!O$2:O$5647,"...",2,-1) -> 2026-0001605 | AC7: =_xlfn.XLOOKUP(H7,'IT PEI'!X$2:X$5647,'IT PEI'!P$2:P$5647,"...",2,-1) -> 46126 | AD7: =_xlfn.XLOOKUP(H7,'IT PEI'!X$2:X$5647,'IT PEI'!Q$2:Q$5647,"...",2,-1) -> 000264-2026-CEPLAN-DNCPPEI | AE7: =IF(COUNTIF(X7, "*" & "2030" & "*")>0, "SI", "No" ) -> SI | AF7: =IF(COUNTIF(X7, "*" & "2030" & "*")>0, 1, 0 ) -> 1 | AG7: =IF(COUNTIF(X7, "*" & "2030" & "*")>0, 0, 1 ) -> 0 | AH7: =IF(AND(AA7="En Proceso",AE7="Si"),1,0) -> 0 | AI7: ACTIVO | AJ7: Leidy Cayotopa Mesones | AK7: leidy.cayotopa.ceplan@gmail.com | AL7: =IFERROR(VLOOKUP(tbl_ues[[#This Row],[Id_UE]],'[1]Directorio v.02'!$H$3:$U$3089,11,FALSE),"") -> Alexandro Fabricio Estremadoyro Koc | AM7: =IFERROR(VLOOKUP(tbl_ues[[#This Row],[Id_UE]],'[1]Directorio v.02'!$H$3:$U$3089,12,FALSE),"") -> Jefe de la Unidad de Planeamiento y Organización | AN7: =IFERROR(VLOOKUP(tbl_ues[[#This Row],[Id_UE]],'[1]Directorio v.02'!$H$3:$U$3089,13,FALSE),"") -> (01)224 2444/ Anexo 1335 | AO7: =IFERROR(VLOOKUP(tbl_ues[[#This Row],[Id_UE]],'[1]Directorio v.02'!$H$3:$U$3089,14,FALSE),"") -> aestremadoyro@atu.gob.pe | AP7: =VLOOKUP(H7,#REF!,7,0) -> #REF! | AQ7: =VLOOKUP(H7,#REF!,9,0) -> #REF! | AR7: =VLOOKUP(H7,#REF!,15,0) -> #REF! | AS7: =VLOOKUP(H7,#REF!,16,0) -> #REF! | AT7: =VLOOKUP(H7,#REF!,17,0) -> #REF! | AU7: =VLOOKUP(H7,#REF!,18,0) -> #REF! | AV7: =VLOOKUP(H7,#REF!,19,0) -> #REF! | AW7: =VLOOKUP(H7,#REF!,20,0) -> #REF! | AX7: =VLOOKUP(H7,#REF!,22,0) -> #REF! | AY7: =VLOOKUP(H7,#REF!,23,0) -> #REF! | AZ7: =VLOOKUP(H7,#REF!,24,0) -> #REF! | BA7: =VLOOKUP(H7,#REF!,25,0) -> #REF! | BB7: =VLOOKUP(H7,#REF!,26,0) -> #REF! | BC7: =VLOOKUP(H7,#REF!,27,0) -> #REF! | BD7: =VLOOKUP(H7,#REF!,29,0) -> #REF! | BE7: =VLOOKUP(H7,#REF!,30,0) -> #REF! | BF7: =VLOOKUP(H7,#REF!,31,0) -> #REF! | BG7: =VLOOKUP(H7,#REF!,32,0) -> #REF! | BH7: =VLOOKUP(H7,#REF!,33,0) -> #REF! | BI7: =VLOOKUP(H7,#REF!,34,0) -> #REF! | BJ7: =VLOOKUP(H7,#REF!,36,0) -> #REF! | BK7: =VLOOKUP(H7,#REF!,37,0) -> #REF! | BL7: =VLOOKUP(H7,#REF!,44,0) -> #REF! | BM7: =VLOOKUP(H7,#REF!,45,0) -> #REF! | BN7: =VLOOKUP(H7,#REF!,46,0) -> #REF! | BO7: =VLOOKUP(H7,#REF!,47,0) -> #REF! | BP7: =VLOOKUP(H7,#REF!,48,0) -> #REF!
A8: Gobierno nacional | B8: Poder Ejecutivo | C8: E | D8: 1 | E8: PRESIDENCIA CONSEJO MINISTROS | F8: 29 | G8: AUTORIDAD NACIONAL DE INFRAESTRUCTURA | H8: 1750 | I8: AUTORIDAD NACIONAL DE INFRAESTRUCTURA | J8: 15 | K8: LIMA | L8: 1 | M8: LIMA | N8: 1 | O8: LIMA | Q8: S | R8: S | W8: =IFERROR(VLOOKUP(H8,'IT PEI'!$X$2:$X$5647,1,0),"...") -> 1750 | X8: =_xlfn.XLOOKUP(H8,'IT PEI'!X$2:X$5647,'IT PEI'!E$2:E$5647,"...",2,-1) -> 2025-2030 | Y8: =_xlfn.XLOOKUP(H8,'IT PEI'!X$2:X$5647,'IT PEI'!G$2:G$5647,"...",2,-1) -> FORMULADO | Z8: =_xlfn.XLOOKUP(H8,'IT PEI'!X$2:X$5647,'IT PEI'!F$2:F$5647,"...",2,-1) -> SI | AA8: =_xlfn.XLOOKUP(H8,'IT PEI'!X$2:X$5647,'IT PEI'!H$2:H$5647,"...",2,-1) -> EMITIDO | AB8: =_xlfn.XLOOKUP(H8,'IT PEI'!X$2:X$5647,'IT PEI'!O$2:O$5647,"...",2,-1) -> 2024-0001068 | AC8: =_xlfn.XLOOKUP(H8,'IT PEI'!X$2:X$5647,'IT PEI'!P$2:P$5647,"...",2,-1) -> 45656 | AD8: =_xlfn.XLOOKUP(H8,'IT PEI'!X$2:X$5647,'IT PEI'!Q$2:Q$5647,"...",2,-1) -> 000487-2024-CEPLAN-DNCPPEI | AE8: =IF(COUNTIF(X8, "*" & "2030" & "*")>0, "SI", "No" ) -> SI | AF8: =IF(COUNTIF(X8, "*" & "2030" & "*")>0, 1, 0 ) -> 1 | AG8: =IF(COUNTIF(X8, "*" & "2030" & "*")>0, 0, 1 ) -> 0 | AH8: =IF(AND(AA8="En Proceso",AE8="Si"),1,0) -> 0 | AI8: ACTIVO | AJ8: Claudia Melendez Mauricio | AK8: claudia.melendez.ceplan@gmail.com | AL8: =IFERROR(VLOOKUP(tbl_ues[[#This Row],[Id_UE]],'[1]Directorio v.02'!$H$3:$U$3089,11,FALSE),"") -> Carlos Chunga | AM8: =IFERROR(VLOOKUP(tbl_ues[[#This Row],[Id_UE]],'[1]Directorio v.02'!$H$3:$U$3089,12,FALSE),"") -> Jefe de la unidad de Planeamiento | AN8: =IFERROR(VLOOKUP(tbl_ues[[#This Row],[Id_UE]],'[1]Directorio v.02'!$H$3:$U$3089,13,FALSE),"") -> 993392829 | AO8: =IFERROR(VLOOKUP(tbl_ues[[#This Row],[Id_UE]],'[1]Directorio v.02'!$H$3:$U$3089,14,FALSE),"") -> cchunga@anin.gob.pe | AP8: =VLOOKUP(H8,#REF!,7,0) -> #REF! | AQ8: =VLOOKUP(H8,#REF!,9,0) -> #REF! | AR8: =VLOOKUP(H8,#REF!,15,0) -> #REF! | AS8: =VLOOKUP(H8,#REF!,16,0) -> #REF! | AT8: =VLOOKUP(H8,#REF!,17,0) -> #REF! | AU8: =VLOOKUP(H8,#REF!,18,0) -> #REF! | AV8: =VLOOKUP(H8,#REF!,19,0) -> #REF! | AW8: =VLOOKUP(H8,#REF!,20,0) -> #REF! | AX8: =VLOOKUP(H8,#REF!,22,0) -> #REF! | AY8: =VLOOKUP(H8,#REF!,23,0) -> #REF! | AZ8: =VLOOKUP(H8,#REF!,24,0) -> #REF! | BA8: =VLOOKUP(H8,#REF!,25,0) -> #REF! | BB8: =VLOOKUP(H8,#REF!,26,0) -> #REF! | BC8: =VLOOKUP(H8,#REF!,27,0) -> #REF! | BD8: =VLOOKUP(H8,#REF!,29,0) -> #REF! | BE8: =VLOOKUP(H8,#REF!,30,0) -> #REF! | BF8: =VLOOKUP(H8,#REF!,31,0) -> #REF! | BG8: =VLOOKUP(H8,#REF!,32,0) -> #REF! | BH8: =VLOOKUP(H8,#REF!,33,0) -> #REF! | BI8: =VLOOKUP(H8,#REF!,34,0) -> #REF! | BJ8: =VLOOKUP(H8,#REF!,36,0) -> #REF! | BK8: =VLOOKUP(H8,#REF!,37,0) -> #REF! | BL8: =VLOOKUP(H8,#REF!,44,0) -> #REF! | BM8: =VLOOKUP(H8,#REF!,45,0) -> #REF! | BN8: =VLOOKUP(H8,#REF!,46,0) -> #REF! | BO8: =VLOOKUP(H8,#REF!,47,0) -> #REF! | BP8: =VLOOKUP(H8,#REF!,48,0) -> #REF!
A9: Gobierno nacional | B9: Poder Ejecutivo | C9: E | D9: 13 | E9: AGRARIO Y DE RIEGO | F9: 164 | G9: AUTORIDAD NACIONAL DEL AGUA - ANA | H9: 1358 | I9: MODERNIZACION DE LA GESTION DE LOS RECURSOS HIDRICOS | J9: 15 | K9: LIMA | L9: 1 | M9: LIMA | N9: 30 | O9: SAN BORJA | R9: S | W9: =IFERROR(VLOOKUP(H9,'IT PEI'!$X$2:$X$5647,1,0),"...") -> ... | X9: =_xlfn.XLOOKUP(H9,'IT PEI'!X$2:X$5647,'IT PEI'!E$2:E$5647,"...",2,-1) -> ... | Y9: =_xlfn.XLOOKUP(H9,'IT PEI'!X$2:X$5647,'IT PEI'!G$2:G$5647,"...",2,-1) -> ... | Z9: =_xlfn.XLOOKUP(H9,'IT PEI'!X$2:X$5647,'IT PEI'!F$2:F$5647,"...",2,-1) -> ... | AA9: =_xlfn.XLOOKUP(H9,'IT PEI'!X$2:X$5647,'IT PEI'!H$2:H$5647,"...",2,-1) -> ... | AB9: =_xlfn.XLOOKUP(H9,'IT PEI'!X$2:X$5647,'IT PEI'!O$2:O$5647,"...",2,-1) -> ... | AC9: =_xlfn.XLOOKUP(H9,'IT PEI'!X$2:X$5647,'IT PEI'!P$2:P$5647,"...",2,-1) -> ... | AD9: =_xlfn.XLOOKUP(H9,'IT PEI'!X$2:X$5647,'IT PEI'!Q$2:Q$5647,"...",2,-1) -> ... | AE9: =IF(COUNTIF(X9, "*" & "2030" & "*")>0, "SI", "No" ) -> No | AF9: =IF(COUNTIF(X9, "*" & "2030" & "*")>0, 1, 0 ) -> 0 | AG9: =IF(COUNTIF(X9, "*" & "2030" & "*")>0, 0, 1 ) -> 1 | AH9: =IF(AND(AA9="En Proceso",AE9="Si"),1,0) -> 0 | AI9: INACTIVO | AJ9: Fatima Amoretti Arteaga | AK9: fatima.amoretti.ceplan@gmail.com | AL9: =IFERROR(VLOOKUP(tbl_ues[[#This Row],[Id_UE]],'[1]Directorio v.02'!$H$3:$U$3089,11,FALSE),"") | AM9: =IFERROR(VLOOKUP(tbl_ues[[#This Row],[Id_UE]],'[1]Directorio v.02'!$H$3:$U$3089,12,FALSE),"") | AN9: =IFERROR(VLOOKUP(tbl_ues[[#This Row],[Id_UE]],'[1]Directorio v.02'!$H$3:$U$3089,13,FALSE),"") | AO9: =IFERROR(VLOOKUP(tbl_ues[[#This Row],[Id_UE]],'[1]Directorio v.02'!$H$3:$U$3089,14,FALSE),"") | AP9: =VLOOKUP(H9,#REF!,7,0) -> #REF! | AQ9: =VLOOKUP(H9,#REF!,9,0) -> #REF! | AR9: =VLOOKUP(H9,#REF!,15,0) -> #REF! | AS9: =VLOOKUP(H9,#REF!,16,0) -> #REF! | AT9: =VLOOKUP(H9,#REF!,17,0) -> #REF! | AU9: =VLOOKUP(H9,#REF!,18,0) -> #REF! | AV9: =VLOOKUP(H9,#REF!,19,0) -> #REF! | AW9: =VLOOKUP(H9,#REF!,20,0) -> #REF! | AX9: =VLOOKUP(H9,#REF!,22,0) -> #REF! | AY9: =VLOOKUP(H9,#REF!,23,0) -> #REF! | AZ9: =VLOOKUP(H9,#REF!,24,0) -> #REF! | BA9: =VLOOKUP(H9,#REF!,25,0) -> #REF! | BB9: =VLOOKUP(H9,#REF!,26,0) -> #REF! | BC9: =VLOOKUP(H9,#REF!,27,0) -> #REF! | BD9: =VLOOKUP(H9,#REF!,29,0) -> #REF! | BE9: =VLOOKUP(H9,#REF!,30,0) -> #REF! | BF9: =VLOOKUP(H9,#REF!,31,0) -> #REF! | BG9: =VLOOKUP(H9,#REF!,32,0) -> #REF! | BH9: =VLOOKUP(H9,#REF!,33,0) -> #REF! | BI9: =VLOOKUP(H9,#REF!,34,0) -> #REF! | BJ9: =VLOOKUP(H9,#REF!,36,0) -> #REF! | BK9: =VLOOKUP(H9,#REF!,37,0) -> #REF! | BL9: =VLOOKUP(H9,#REF!,44,0) -> #REF! | BM9: =VLOOKUP(H9,#REF!,45,0) -> #REF! | BN9: =VLOOKUP(H9,#REF!,46,0) -> #REF! | BO9: =VLOOKUP(H9,#REF!,47,0) -> #REF! | BP9: =VLOOKUP(H9,#REF!,48,0) -> #REF!
A10: Gobierno nacional | B10: Poder Ejecutivo | C10: E | D10: 13 | E10: AGRARIO Y DE RIEGO | F10: 164 | G10: AUTORIDAD NACIONAL DEL AGUA - ANA | H10: 1299 | I10: AUTORIDAD NACIONAL DE AGUA - SEDE CENTRAL | J10: 15 | K10: LIMA | L10: 1 | M10: LIMA | N10: 31 | O10: SAN ISIDRO | Q10: S | R10: S | W10: =IFERROR(VLOOKUP(H10,'IT PEI'!$X$2:$X$5647,1,0),"...") -> 1299 | X10: =_xlfn.XLOOKUP(H10,'IT PEI'!X$2:X$5647,'IT PEI'!E$2:E$5647,"...",2,-1) -> 2025-2030 | Y10: =_xlfn.XLOOKUP(H10,'IT PEI'!X$2:X$5647,'IT PEI'!G$2:G$5647,"...",2,-1) -> FORMULADO | Z10: =_xlfn.XLOOKUP(H10,'IT PEI'!X$2:X$5647,'IT PEI'!F$2:F$5647,"...",2,-1) -> SI | AA10: =_xlfn.XLOOKUP(H10,'IT PEI'!X$2:X$5647,'IT PEI'!H$2:H$5647,"...",2,-1) -> EMITIDO | AB10: =_xlfn.XLOOKUP(H10,'IT PEI'!X$2:X$5647,'IT PEI'!O$2:O$5647,"...",2,-1) -> 2024-0003569 | AC10: =_xlfn.XLOOKUP(H10,'IT PEI'!X$2:X$5647,'IT PEI'!P$2:P$5647,"...",2,-1) -> 45628 | AD10: =_xlfn.XLOOKUP(H10,'IT PEI'!X$2:X$5647,'IT PEI'!Q$2:Q$5647,"...",2,-1) -> 000404-2024-CEPLAN-DNCPPEI | AE10: =IF(COUNTIF(X10, "*" & "2030" & "*")>0, "SI", "No" ) -> SI | AF10: =IF(COUNTIF(X10, "*" & "2030" & "*")>0, 1, 0 ) -> 1 | AG10: =IF(COUNTIF(X10, "*" & "2030" & "*")>0, 0, 1 ) -> 0 | AH10: =IF(AND(AA10="En Proceso",AE10="Si"),1,0) -> 0 | AI10: ACTIVO | AJ10: Fatima Amoretti Arteaga | AK10: fatima.amoretti.ceplan@gmail.com | AL10: =IFERROR(VLOOKUP(tbl_ues[[#This Row],[Id_UE]],'[1]Directorio v.02'!$H$3:$U$3089,11,FALSE),"") -> Cpcc. Johnny César Cayo Saravia | AM10: =IFERROR(VLOOKUP(tbl_ues[[#This Row],[Id_UE]],'[1]Directorio v.02'!$H$3:$U$3089,12,FALSE),"") -> Director Oficina de Planeamiento y Presupuesto | AN10: =IFERROR(VLOOKUP(tbl_ues[[#This Row],[Id_UE]],'[1]Directorio v.02'!$H$3:$U$3089,13,FALSE),"") -> 224-3298 A. 1409 | AO10: =IFERROR(VLOOKUP(tbl_ues[[#This Row],[Id_UE]],'[1]Directorio v.02'!$H$3:$U$3089,14,FALSE),"") -> ccayo@ana.gob.pe | AP10: =VLOOKUP(H10,#REF!,7,0) -> #REF! | AQ10: =VLOOKUP(H10,#REF!,9,0) -> #REF! | AR10: =VLOOKUP(H10,#REF!,15,0) -> #REF! | AS10: =VLOOKUP(H10,#REF!,16,0) -> #REF! | AT10: =VLOOKUP(H10,#REF!,17,0) -> #REF! | AU10: =VLOOKUP(H10,#REF!,18,0) -> #REF! | AV10: =VLOOKUP(H10,#REF!,19,0) -> #REF! | AW10: =VLOOKUP(H10,#REF!,20,0) -> #REF! | AX10: =VLOOKUP(H10,#REF!,22,0) -> #REF! | AY10: =VLOOKUP(H10,#REF!,23,0) -> #REF! | AZ10: =VLOOKUP(H10,#REF!,24,0) -> #REF! | BA10: =VLOOKUP(H10,#REF!,25,0) -> #REF! | BB10: =VLOOKUP(H10,#REF!,26,0) -> #REF! | BC10: =VLOOKUP(H10,#REF!,27,0) -> #REF! | BD10: =VLOOKUP(H10,#REF!,29,0) -> #REF! | BE10: =VLOOKUP(H10,#REF!,30,0) -> #REF! | BF10: =VLOOKUP(H10,#REF!,31,0) -> #REF! | BG10: =VLOOKUP(H10,#REF!,32,0) -> #REF! | BH10: =VLOOKUP(H10,#REF!,33,0) -> #REF! | BI10: =VLOOKUP(H10,#REF!,34,0) -> #REF! | BJ10: =VLOOKUP(H10,#REF!,36,0) -> #REF! | BK10: =VLOOKUP(H10,#REF!,37,0) -> #REF! | BL10: =VLOOKUP(H10,#REF!,44,0) -> #REF! | BM10: =VLOOKUP(H10,#REF!,45,0) -> #REF! | BN10: =VLOOKUP(H10,#REF!,46,0) -> #REF! | BO10: =VLOOKUP(H10,#REF!,47,0) -> #REF! | BP10: =VLOOKUP(H10,#REF!,48,0) -> #REF!
A11: Gobierno nacional | B11: Poder Ejecutivo | C11: E | D11: 1 | E11: PRESIDENCIA CONSEJO MINISTROS | F11: 23 | G11: AUTORIDAD NACIONAL DEL SERVICIO CIVIL | H11: 1314 | I11: AUTORIDAD NACIONAL DE SERVICIO CIVIL | J11: 15 | K11: LIMA | L11: 1 | M11: LIMA | N11: 13 | O11: JESUS MARIA | Q11: S | R11: S | W11: =IFERROR(VLOOKUP(H11,'IT PEI'!$X$2:$X$5647,1,0),"...") -> 1314 | X11: =_xlfn.XLOOKUP(H11,'IT PEI'!X$2:X$5647,'IT PEI'!E$2:E$5647,"...",2,-1) -> 2025-2030 | Y11: =_xlfn.XLOOKUP(H11,'IT PEI'!X$2:X$5647,'IT PEI'!G$2:G$5647,"...",2,-1) -> FORMULADO | Z11: =_xlfn.XLOOKUP(H11,'IT PEI'!X$2:X$5647,'IT PEI'!F$2:F$5647,"...",2,-1) -> SI | AA11: =_xlfn.XLOOKUP(H11,'IT PEI'!X$2:X$5647,'IT PEI'!H$2:H$5647,"...",2,-1) -> EMITIDO | AB11: =_xlfn.XLOOKUP(H11,'IT PEI'!X$2:X$5647,'IT PEI'!O$2:O$5647,"...",2,-1) -> 2024-0003871 | AC11: =_xlfn.XLOOKUP(H11,'IT PEI'!X$2:X$5647,'IT PEI'!P$2:P$5647,"...",2,-1) -> 45645 | AD11: =_xlfn.XLOOKUP(H11,'IT PEI'!X$2:X$5647,'IT PEI'!Q$2:Q$5647,"...",2,-1) -> 000448-2024-CEPLAN-DNCPPEI | AE11: =IF(COUNTIF(X11, "*" & "2030" & "*")>0, "SI", "No" ) -> SI | AF11: =IF(COUNTIF(X11, "*" & "2030" & "*")>0, 1, 0 ) -> 1 | AG11: =IF(COUNTIF(X11, "*" & "2030" & "*")>0, 0, 1 ) -> 0 | AH11: =IF(AND(AA11="En Proceso",AE11="Si"),1,0) -> 0 | AI11: ACTIVO | AJ11: Claudia Melendez Mauricio | AK11: claudia.melendez.ceplan@gmail.com | AL11: =IFERROR(VLOOKUP(tbl_ues[[#This Row],[Id_UE]],'[1]Directorio v.02'!$H$3:$U$3089,11,FALSE),"") -> Irwing Aspajo Grandez | AM11: =IFERROR(VLOOKUP(tbl_ues[[#This Row],[Id_UE]],'[1]Directorio v.02'!$H$3:$U$3089,12,FALSE),"") -> Jefe de la Oficina de Planeamiento y Presupuesto | AN11: =IFERROR(VLOOKUP(tbl_ues[[#This Row],[Id_UE]],'[1]Directorio v.02'!$H$3:$U$3089,13,FALSE),"") -> 964419164 | AO11: =IFERROR(VLOOKUP(tbl_ues[[#This Row],[Id_UE]],'[1]Directorio v.02'!$H$3:$U$3089,14,FALSE),"") -> iaspajo@servir.gob.pe | AP11: =VLOOKUP(H11,#REF!,7,0) -> #REF! | AQ11: =VLOOKUP(H11,#REF!,9,0) -> #REF! | AR11: =VLOOKUP(H11,#REF!,15,0) -> #REF! | AS11: =VLOOKUP(H11,#REF!,16,0) -> #REF! | AT11: =VLOOKUP(H11,#REF!,17,0) -> #REF! | AU11: =VLOOKUP(H11,#REF!,18,0) -> #REF! | AV11: =VLOOKUP(H11,#REF!,19,0) -> #REF! | AW11: =VLOOKUP(H11,#REF!,20,0) -> #REF! | AX11: =VLOOKUP(H11,#REF!,22,0) -> #REF! | AY11: =VLOOKUP(H11,#REF!,23,0) -> #REF! | AZ11: =VLOOKUP(H11,#REF!,24,0) -> #REF! | BA11: =VLOOKUP(H11,#REF!,25,0) -> #REF! | BB11: =VLOOKUP(H11,#REF!,26,0) -> #REF! | BC11: =VLOOKUP(H11,#REF!,27,0) -> #REF! | BD11: =VLOOKUP(H11,#REF!,29,0) -> #REF! | BE11: =VLOOKUP(H11,#REF!,30,0) -> #REF! | BF11: =VLOOKUP(H11,#REF!,31,0) -> #REF! | BG11: =VLOOKUP(H11,#REF!,32,0) -> #REF! | BH11: =VLOOKUP(H11,#REF!,33,0) -> #REF! | BI11: =VLOOKUP(H11,#REF!,34,0) -> #REF! | BJ11: =VLOOKUP(H11,#REF!,36,0) -> #REF! | BK11: =VLOOKUP(H11,#REF!,37,0) -> #REF! | BL11: =VLOOKUP(H11,#REF!,44,0) -> #REF! | BM11: =VLOOKUP(H11,#REF!,45,0) -> #REF! | BN11: =VLOOKUP(H11,#REF!,46,0) -> #REF! | BO11: =VLOOKUP(H11,#REF!,47,0) -> #REF! | BP11: =VLOOKUP(H11,#REF!,48,0) -> #REF!
A12: Gobierno nacional | B12: Poder Ejecutivo | C12: E | D12: 36 | E12: TRANSPORTES Y COMUNICACIONES | F12: 214 | G12: AUTORIDAD PORTUARIA NACIONAL | H12: 1205 | I12: AUTORIDAD PORTUARIA NACIONAL | J12: 07 | K12: PROVINCIA CONSTITUCIONAL DEL CALLAO | L12: 1 | M12: CALLAO | N12: 4 | O12: LA PERLA | Q12: S | R12: S | W12: =IFERROR(VLOOKUP(H12,'IT PEI'!$X$2:$X$5647,1,0),"...") -> 1205 | X12: =_xlfn.XLOOKUP(H12,'IT PEI'!X$2:X$5647,'IT PEI'!E$2:E$5647,"...",2,-1) -> 2024-2030 | Y12: =_xlfn.XLOOKUP(H12,'IT PEI'!X$2:X$5647,'IT PEI'!G$2:G$5647,"...",2,-1) -> FORMULADO | Z12: =_xlfn.XLOOKUP(H12,'IT PEI'!X$2:X$5647,'IT PEI'!F$2:F$5647,"...",2,-1) -> SI | AA12: =_xlfn.XLOOKUP(H12,'IT PEI'!X$2:X$5647,'IT PEI'!H$2:H$5647,"...",2,-1) -> EMITIDO | AB12: =_xlfn.XLOOKUP(H12,'IT PEI'!X$2:X$5647,'IT PEI'!O$2:O$5647,"...",2,-1) -> 2024-000236 | AC12: =_xlfn.XLOOKUP(H12,'IT PEI'!X$2:X$5647,'IT PEI'!P$2:P$5647,"...",2,-1) -> 45379 | AD12: =_xlfn.XLOOKUP(H12,'IT PEI'!X$2:X$5647,'IT PEI'!Q$2:Q$5647,"...",2,-1) -> 000145-2024-CEPLAN-DNCPPEI | AE12: =IF(COUNTIF(X12, "*" & "2030" & "*")>0, "SI", "No" ) -> SI | AF12: =IF(COUNTIF(X12, "*" & "2030" & "*")>0, 1, 0 ) -> 1 | AG12: =IF(COUNTIF(X12, "*" & "2030" & "*")>0, 0, 1 ) -> 0 | AH12: =IF(AND(AA12="En Proceso",AE12="Si"),1,0) -> 0 | AI12: ACTIVO | AJ12: Leidy Cayotopa Mesones | AK12: leidy.cayotopa.ceplan@gmail.com | AL12: =IFERROR(VLOOKUP(tbl_ues[[#This Row],[Id_UE]],'[1]Directorio v.02'!$H$3:$U$3089,11,FALSE),"") -> Ricardo Javier Guimaray Hernández | AM12: =IFERROR(VLOOKUP(tbl_ues[[#This Row],[Id_UE]],'[1]Directorio v.02'!$H$3:$U$3089,12,FALSE),"") -> Director de Planeamiento y Estudios Económicos | AN12: =IFERROR(VLOOKUP(tbl_ues[[#This Row],[Id_UE]],'[1]Directorio v.02'!$H$3:$U$3089,13,FALSE),"") -> 630 9600 Anx. 1706 | AO12: =IFERROR(VLOOKUP(tbl_ues[[#This Row],[Id_UE]],'[1]Directorio v.02'!$H$3:$U$3089,14,FALSE),"") -> rguimaray@apn.gob.pe | AP12: =VLOOKUP(H12,#REF!,7,0) -> #REF! | AQ12: =VLOOKUP(H12,#REF!,9,0) -> #REF! | AR12: =VLOOKUP(H12,#REF!,15,0) -> #REF! | AS12: =VLOOKUP(H12,#REF!,16,0) -> #REF! | AT12: =VLOOKUP(H12,#REF!,17,0) -> #REF! | AU12: =VLOOKUP(H12,#REF!,18,0) -> #REF! | AV12: =VLOOKUP(H12,#REF!,19,0) -> #REF! | AW12: =VLOOKUP(H12,#REF!,20,0) -> #REF! | AX12: =VLOOKUP(H12,#REF!,22,0) -> #REF! | AY12: =VLOOKUP(H12,#REF!,23,0) -> #REF! | AZ12: =VLOOKUP(H12,#REF!,24,0) -> #REF! | BA12: =VLOOKUP(H12,#REF!,25,0) -> #REF! | BB12: =VLOOKUP(H12,#REF!,26,0) -> #REF! | BC12: =VLOOKUP(H12,#REF!,27,0) -> #REF! | BD12: =VLOOKUP(H12,#REF!,29,0) -> #REF! | BE12: =VLOOKUP(H12,#REF!,30,0) -> #REF! | BF12: =VLOOKUP(H12,#REF!,31,0) -> #REF! | BG12: =VLOOKUP(H12,#REF!,32,0) -> #REF! | BH12: =VLOOKUP(H12,#REF!,33,0) -> #REF! | BI12: =VLOOKUP(H12,#REF!,34,0) -> #REF! | BJ12: =VLOOKUP(H12,#REF!,36,0) -> #REF! | BK12: =VLOOKUP(H12,#REF!,37,0) -> #REF! | BL12: =VLOOKUP(H12,#REF!,44,0) -> #REF! | BM12: =VLOOKUP(H12,#REF!,45,0) -> #REF! | BN12: =VLOOKUP(H12,#REF!,46,0) -> #REF! | BO12: =VLOOKUP(H12,#REF!,47,0) -> #REF! | BP12: =VLOOKUP(H12,#REF!,48,0) -> #REF!
A13: Gobierno nacional | B13: Poder Ejecutivo | C13: E | D13: 3 | E13: CULTURA | F13: 113 | G13: BIBLIOTECA NACIONAL DEL PERU | H13: 85 | I13: BIBLIOTECA NACIONAL DEL PERU | J13: 15 | K13: LIMA | L13: 1 | M13: LIMA | N13: 1 | O13: LIMA | Q13: S | R13: S | W13: =IFERROR(VLOOKUP(H13,'IT PEI'!$X$2:$X$5647,1,0),"...") -> 85 | X13: =_xlfn.XLOOKUP(H13,'IT PEI'!X$2:X$5647,'IT PEI'!E$2:E$5647,"...",2,-1) -> 2023-2030 | Y13: =_xlfn.XLOOKUP(H13,'IT PEI'!X$2:X$5647,'IT PEI'!G$2:G$5647,"...",2,-1) -> MODIFICADO | Z13: =_xlfn.XLOOKUP(H13,'IT PEI'!X$2:X$5647,'IT PEI'!F$2:F$5647,"...",2,-1) -> SI | AA13: =_xlfn.XLOOKUP(H13,'IT PEI'!X$2:X$5647,'IT PEI'!H$2:H$5647,"...",2,-1) -> EMITIDO | AB13: =_xlfn.XLOOKUP(H13,'IT PEI'!X$2:X$5647,'IT PEI'!O$2:O$5647,"...",2,-1) -> 2024-0000981 | AC13: =_xlfn.XLOOKUP(H13,'IT PEI'!X$2:X$5647,'IT PEI'!P$2:P$5647,"...",2,-1) -> 45377 | AD13: =_xlfn.XLOOKUP(H13,'IT PEI'!X$2:X$5647,'IT PEI'!Q$2:Q$5647,"...",2,-1) -> 000123-2024-CEPLAN-DNCPPEI | AE13: =IF(COUNTIF(X13, "*" & "2030" & "*")>0, "SI", "No" ) -> SI | AF13: =IF(COUNTIF(X13, "*" & "2030" & "*")>0, 1, 0 ) -> 1 | AG13: =IF(COUNTIF(X13, "*" & "2030" & "*")>0, 0, 1 ) -> 0 | AH13: =IF(AND(AA13="En Proceso",AE13="Si"),1,0) -> 0 | AI13: ACTIVO | AJ13: Lourdes Gutierrez Aguado | AK13: lgutierrez@ceplan.gob.pe | AL13: =IFERROR(VLOOKUP(tbl_ues[[#This Row],[Id_UE]],'[1]Directorio v.02'!$H$3:$U$3089,11,FALSE),"") -> Erika Romero Estela | AM13: =IFERROR(VLOOKUP(tbl_ues[[#This Row],[Id_UE]],'[1]Directorio v.02'!$H$3:$U$3089,12,FALSE),"") -> Jefe de la Oficina de Planeamiento y Presupuesto | AN13: =IFERROR(VLOOKUP(tbl_ues[[#This Row],[Id_UE]],'[1]Directorio v.02'!$H$3:$U$3089,13,FALSE),"") -> 513-6900 - Anexo 7400 | AO13: =IFERROR(VLOOKUP(tbl_ues[[#This Row],[Id_UE]],'[1]Directorio v.02'!$H$3:$U$3089,14,FALSE),"") -> erika.romero@bnp.gob.pe | AP13: =VLOOKUP(H13,#REF!,7,0) -> #REF! | AQ13: =VLOOKUP(H13,#REF!,9,0) -> #REF! | AR13: =VLOOKUP(H13,#REF!,15,0) -> #REF! | AS13: =VLOOKUP(H13,#REF!,16,0) -> #REF! | AT13: =VLOOKUP(H13,#REF!,17,0) -> #REF! | AU13: =VLOOKUP(H13,#REF!,18,0) -> #REF! | AV13: =VLOOKUP(H13,#REF!,19,0) -> #REF! | AW13: =VLOOKUP(H13,#REF!,20,0) -> #REF! | AX13: =VLOOKUP(H13,#REF!,22,0) -> #REF! | AY13: =VLOOKUP(H13,#REF!,23,0) -> #REF! | AZ13: =VLOOKUP(H13,#REF!,24,0) -> #REF! | BA13: =VLOOKUP(H13,#REF!,25,0) -> #REF! | BB13: =VLOOKUP(H13,#REF!,26,0) -> #REF! | BC13: =VLOOKUP(H13,#REF!,27,0) -> #REF! | BD13: =VLOOKUP(H13,#REF!,29,0) -> #REF! | BE13: =VLOOKUP(H13,#REF!,30,0) -> #REF! | BF13: =VLOOKUP(H13,#REF!,31,0) -> #REF! | BG13: =VLOOKUP(H13,#REF!,32,0) -> #REF! | BH13: =VLOOKUP(H13,#REF!,33,0) -> #REF! | BI13: =VLOOKUP(H13,#REF!,34,0) -> #REF! | BJ13: =VLOOKUP(H13,#REF!,36,0) -> #REF! | BK13: =VLOOKUP(H13,#REF!,37,0) -> #REF! | BL13: =VLOOKUP(H13,#REF!,44,0) -> #REF! | BM13: =VLOOKUP(H13,#REF!,45,0) -> #REF! | BN13: =VLOOKUP(H13,#REF!,46,0) -> #REF! | BO13: =VLOOKUP(H13,#REF!,47,0) -> #REF! | BP13: =VLOOKUP(H13,#REF!,48,0) -> #REF!
A14: Gobierno nacional | B14: Poder Ejecutivo | C14: E | D14: 9 | E14: ECONOMIA Y FINANZAS | F14: 96 | G14: CENTRAL DE COMPRAS PÚBLICAS - PERÚ COMPRAS | H14: 1650 | I14: CENTRAL DE COMPRAS PUBLICAS - PERU COMPRAS | J14: 15 | K14: LIMA | L14: 1 | M14: LIMA | N14: 31 | O14: SAN ISIDRO | Q14: S | R14: S | W14: =IFERROR(VLOOKUP(H14,'IT PEI'!$X$2:$X$5647,1,0),"...") -> 1650 | X14: =_xlfn.XLOOKUP(H14,'IT PEI'!X$2:X$5647,'IT PEI'!E$2:E$5647,"...",2,-1) -> 2026-2030 | Y14: =_xlfn.XLOOKUP(H14,'IT PEI'!X$2:X$5647,'IT PEI'!G$2:G$5647,"...",2,-1) -> FORMULADO | Z14: =_xlfn.XLOOKUP(H14,'IT PEI'!X$2:X$5647,'IT PEI'!F$2:F$5647,"...",2,-1) -> SI | AA14: =_xlfn.XLOOKUP(H14,'IT PEI'!X$2:X$5647,'IT PEI'!H$2:H$5647,"...",2,-1) -> EMITIDO | AB14: =_xlfn.XLOOKUP(H14,'IT PEI'!X$2:X$5647,'IT PEI'!O$2:O$5647,"...",2,-1) -> 2026-0000210 | AC14: =_xlfn.XLOOKUP(H14,'IT PEI'!X$2:X$5647,'IT PEI'!P$2:P$5647,"...",2,-1) -> 46037 | AD14: =_xlfn.XLOOKUP(H14,'IT PEI'!X$2:X$5647,'IT PEI'!Q$2:Q$5647,"...",2,-1) -> 000016-2026-CEPLAN-DNCPPEI | AE14: =IF(COUNTIF(X14, "*" & "2030" & "*")>0, "SI", "No" ) -> SI | AF14: =IF(COUNTIF(X14, "*" & "2030" & "*")>0, 1, 0 ) -> 1 | AG14: =IF(COUNTIF(X14, "*" & "2030" & "*")>0, 0, 1 ) -> 0 | AH14: =IF(AND(AA14="En Proceso",AE14="Si"),1,0) -> 0 | AI14: ACTIVO | AJ14: Fatima Amoretti Arteaga | AK14: fatima.amoretti.ceplan@gmail.com | AL14: =IFERROR(VLOOKUP(tbl_ues[[#This Row],[Id_UE]],'[1]Directorio v.02'!$H$3:$U$3089,11,FALSE),"") -> Milagros Esperanza Guerrero Barrera | AM14: =IFERROR(VLOOKUP(tbl_ues[[#This Row],[Id_UE]],'[1]Directorio v.02'!$H$3:$U$3089,12,FALSE),"") -> Jefe de la Oficina de Planeamiento y Presupuesto | AN14: =IFERROR(VLOOKUP(tbl_ues[[#This Row],[Id_UE]],'[1]Directorio v.02'!$H$3:$U$3089,13,FALSE),"") -> 962826260 | AO14: =IFERROR(VLOOKUP(tbl_ues[[#This Row],[Id_UE]],'[1]Directorio v.02'!$H$3:$U$3089,14,FALSE),"") -> milagros.guerrero@perucompras.gob.pe | AP14: =VLOOKUP(H14,#REF!,7,0) -> #REF! | AQ14: =VLOOKUP(H14,#REF!,9,0) -> #REF! | AR14: =VLOOKUP(H14,#REF!,15,0) -> #REF! | AS14: =VLOOKUP(H14,#REF!,16,0) -> #REF! | AT14: =VLOOKUP(H14,#REF!,17,0) -> #REF! | AU14: =VLOOKUP(H14,#REF!,18,0) -> #REF! | AV14: =VLOOKUP(H14,#REF!,19,0) -> #REF! | AW14: =VLOOKUP(H14,#REF!,20,0) -> #REF! | AX14: =VLOOKUP(H14,#REF!,22,0) -> #REF! | AY14: =VLOOKUP(H14,#REF!,23,0) -> #REF! | AZ14: =VLOOKUP(H14,#REF!,24,0) -> #REF! | BA14: =VLOOKUP(H14,#REF!,25,0) -> #REF! | BB14: =VLOOKUP(H14,#REF!,26,0) -> #REF! | BC14: =VLOOKUP(H14,#REF!,27,0) -> #REF! | BD14: =VLOOKUP(H14,#REF!,29,0) -> #REF! | BE14: =VLOOKUP(H14,#REF!,30,0) -> #REF! | BF14: =VLOOKUP(H14,#REF!,31,0) -> #REF! | BG14: =VLOOKUP(H14,#REF!,32,0) -> #REF! | BH14: =VLOOKUP(H14,#REF!,33,0) -> #REF! | BI14: =VLOOKUP(H14,#REF!,34,0) -> #REF! | BJ14: =VLOOKUP(H14,#REF!,36,0) -> #REF! | BK14: =VLOOKUP(H14,#REF!,37,0) -> #REF! | BL14: =VLOOKUP(H14,#REF!,44,0) -> #REF! | BM14: =VLOOKUP(H14,#REF!,45,0) -> #REF! | BN14: =VLOOKUP(H14,#REF!,46,0) -> #REF! | BO14: =VLOOKUP(H14,#REF!,47,0) -> #REF! | BP14: =VLOOKUP(H14,#REF!,48,0) -> #REF!
A15: Gobierno nacional | B15: Poder Ejecutivo | C15: E | D15: 35 | E15: COMERCIO EXTERIOR Y TURISMO | F15: 180 | G15: CENTRO DE FORMACION EN TURISMO | H15: 162 | I15: CENTRO DE FORMACION EN TURISMO | J15: 15 | K15: LIMA | L15: 1 | M15: LIMA | N15: 4 | O15: BARRANCO | Q15: S | R15: S | W15: =IFERROR(VLOOKUP(H15,'IT PEI'!$X$2:$X$5647,1,0),"...") -> 162 | X15: =_xlfn.XLOOKUP(H15,'IT PEI'!X$2:X$5647,'IT PEI'!E$2:E$5647,"...",2,-1) -> 2026-2030 | Y15: =_xlfn.XLOOKUP(H15,'IT PEI'!X$2:X$5647,'IT PEI'!G$2:G$5647,"...",2,-1) -> FORMULADO | Z15: =_xlfn.XLOOKUP(H15,'IT PEI'!X$2:X$5647,'IT PEI'!F$2:F$5647,"...",2,-1) -> SI | AA15: =_xlfn.XLOOKUP(H15,'IT PEI'!X$2:X$5647,'IT PEI'!H$2:H$5647,"...",2,-1) -> EMITIDO | AB15: =_xlfn.XLOOKUP(H15,'IT PEI'!X$2:X$5647,'IT PEI'!O$2:O$5647,"...",2,-1) -> 2026-0000087 | AC15: =_xlfn.XLOOKUP(H15,'IT PEI'!X$2:X$5647,'IT PEI'!P$2:P$5647,"...",2,-1) -> 46030 | AD15: =_xlfn.XLOOKUP(H15,'IT PEI'!X$2:X$5647,'IT PEI'!Q$2:Q$5647,"...",2,-1) -> 000004-2026-CEPLAN-DNCPPEI | AE15: =IF(COUNTIF(X15, "*" & "2030" & "*")>0, "SI", "No" ) -> SI | AF15: =IF(COUNTIF(X15, "*" & "2030" & "*")>0, 1, 0 ) -> 1 | AG15: =IF(COUNTIF(X15, "*" & "2030" & "*")>0, 0, 1 ) -> 0 | AH15: =IF(AND(AA15="En Proceso",AE15="Si"),1,0) -> 0 | AI15: ACTIVO | AJ15: Marco Condori Lozano | AK15: mcondori@ceplan.gob.pe | AL15: =IFERROR(VLOOKUP(tbl_ues[[#This Row],[Id_UE]],'[1]Directorio v.02'!$H$3:$U$3089,11,FALSE),"") -> Mijail Alva Muñoz | AM15: =IFERROR(VLOOKUP(tbl_ues[[#This Row],[Id_UE]],'[1]Directorio v.02'!$H$3:$U$3089,12,FALSE),"") -> Jefe (E ) de la Unidad de Planeamiento y Desarrollo | AN15: =IFERROR(VLOOKUP(tbl_ues[[#This Row],[Id_UE]],'[1]Directorio v.02'!$H$3:$U$3089,13,FALSE),"") -> 956-480-240 | AO15: =IFERROR(VLOOKUP(tbl_ues[[#This Row],[Id_UE]],'[1]Directorio v.02'!$H$3:$U$3089,14,FALSE),"") -> malva@cenfotur.edu.pe | AP15: =VLOOKUP(H15,#REF!,7,0) -> #REF! | AQ15: =VLOOKUP(H15,#REF!,9,0) -> #REF! | AR15: =VLOOKUP(H15,#REF!,15,0) -> #REF! | AS15: =VLOOKUP(H15,#REF!,16,0) -> #REF! | AT15: =VLOOKUP(H15,#REF!,17,0) -> #REF! | AU15: =VLOOKUP(H15,#REF!,18,0) -> #REF! | AV15: =VLOOKUP(H15,#REF!,19,0) -> #REF! | AW15: =VLOOKUP(H15,#REF!,20,0) -> #REF! | AX15: =VLOOKUP(H15,#REF!,22,0) -> #REF! | AY15: =VLOOKUP(H15,#REF!,23,0) -> #REF! | AZ15: =VLOOKUP(H15,#REF!,24,0) -> #REF! | BA15: =VLOOKUP(H15,#REF!,25,0) -> #REF! | BB15: =VLOOKUP(H15,#REF!,26,0) -> #REF! | BC15: =VLOOKUP(H15,#REF!,27,0) -> #REF! | BD15: =VLOOKUP(H15,#REF!,29,0) -> #REF! | BE15: =VLOOKUP(H15,#REF!,30,0) -> #REF! | BF15: =VLOOKUP(H15,#REF!,31,0) -> #REF! | BG15: =VLOOKUP(H15,#REF!,32,0) -> #REF! | BH15: =VLOOKUP(H15,#REF!,33,0) -> #REF! | BI15: =VLOOKUP(H15,#REF!,34,0) -> #REF! | BJ15: =VLOOKUP(H15,#REF!,36,0) -> #REF! | BK15: =VLOOKUP(H15,#REF!,37,0) -> #REF! | BL15: =VLOOKUP(H15,#REF!,44,0) -> #REF! | BM15: =VLOOKUP(H15,#REF!,45,0) -> #REF! | BN15: =VLOOKUP(H15,#REF!,46,0) -> #REF! | BO15: =VLOOKUP(H15,#REF!,47,0) -> #REF! | BP15: =VLOOKUP(H15,#REF!,48,0) -> #REF!
